Workbook

Sheet Parametri
A1: MODELLO QUANTITATIVO DELLA PROPOSTA DI RIFORMA PENSIONISTICA — v2 (16/05/2026)
A2: Foglio dei parametri — celle gialle = ipotesi chiave; celle verdi = parametri aggiunti rispetto a v1
A4: Parametro | B4: Valore | C4: Unità | D4: Note metodologiche | E4: Fonte
A5: DEMOGRAFIA E MACRO
A6: Anno iniziale | B6: 2026 | C6: anno | D6: Anno di partenza simulazione | E6: RGS 26/2025
A7: Orizzonte temporale | B7: 30 | C7: anni | D7: 2026-2055 | E7: Coerente con orizzonte Australia SG (33 anni 1992-2025)
A8: Pensionati distinti (anno 0) | B8: 16.3 | C8: mln | D8: Pensionati fisici al 31/12/2024 (cumulo 1,41 pensioni/persona) | E8: INPS Osservatorio 2024
A9: Pensioni vigenti (anno 0) | B9: 21.3 | C9: mln | D9: VARIABILE OPERATIVA del modello: il PAYG eroga prestazioni, non persone | E9: INPS Osservatorio Pensioni Vigenti 1.1.2026, Tav. 13
A10: Cumulo medio pensioni/pensionato | B10: 1.41 | C10: n | D10: 21,3/16,3 = 1,41 — strutturale (vecchiaia+reversibilità) | E10: INPS Casellario 31/12/2024
A11: Occupati dipendenti privati (FPLD) | B11: 14 | C11: mln | D11: Perimetro Livello 1 base | E11: INPS-FPLD 2024
A12: Occupati dipendenti pubblici (CTPS) | B12: 3.5 | C12: mln | D12: AGGIUNTO al Livello 1: pubblici impiegati gestione separata CTPS | E12: INPS CTPS 2024
A13: Totale occupati Livello 1 | B13: 17.5 | C13: mln | D13: Dipendenti privati + pubblici — perimetro modello base | E13: Somma
A14: Crescita reale pensioni vigenti | B14: 0.01 | C14: %/anno | D14: Trend invecchiamento, ipotesi conservativa | E14: ISTAT proiezioni base 1.1.2024
A15: Crescita reale occupati (al netto migrazione) | B15: -0.005 | C15: %/anno | D15: Trend demografico ISTAT base 2024 | E15: ISTAT
A16: Migrazione netta annua (scenario RGS) | B16: 165000 | C16: persone/anno | D16: 165k/anno per 50 anni — Scenario base RGS Rapporto 26/2025 | E16: RGS 26/2025; OCPI Cattolica 27/02/2026
A17: Quota migranti in età lavorativa | B17: 0.7 | C17: % | D17: Stima Moressa: ~70% migranti sono 25-54 | E17: Moressa XV Rapporto 2025
... A22: Crescita reale salari (g_w) | B22: 0.002 | C22: %/anno | D22: CORRETTO dal +0,5% v1 a +0,05%: Eurostat ILC_DI03 mostra reale NEGATIVO per coorti attive 2005-2024 | E22: Eurostat ILC_DI03 + HICP 2005-2024
A24: SISTEMA ATTUALE (PAYG)
A25: Aliquota contributiva (dipendenti) | B25: 0.33 | C25: % | D25: 9,19% lavoratore + 23,81% datore | E25: INPS aliquote 2024
A26: Pensione media mensile (singola prestazione) | B26: 1218 | C26: €/mese | D26: AGGIORNATO: importo medio della SINGOLA prestazione (era 1.350 = pens. di vecchiaia) | E26: INPS Osservatorio 2024 — Q5 Bertonelli
A27: Reddito medio del pensionato | B27: 1718 | C27: €/mese | D27: 22.331 €/anno / 13 — somma 1,41 pensioni cumulate | E27: INPS Casellario 2024
A28: Mensilità annue | B28: 13 | C28: n | D28: Standard previdenziale italiano | E28: Norma
A29: Età pensionabile legale | B29: 67 | C29: anni | D29: Vecchiaia 2026 (Riforma Fornero) | E29: L. 214/2011
A30: Età pensionabile effettiva | B30: 63.8 | C30: anni | D30: AGGIUNTA: età effettiva media INPS 2024 (privati+autonomi) | E30: INPS XXIV Rapporto 2025
A31: Coefficiente trasformazione a 67 anni | B31: 0.05608 | C31: % | D31: AGGIORNATO 5,723%→5,608% biennio 2025-2026 | E31: DM MEF 20/11/2024
A32: Spesa PAYG/PIL anno 0 (status quo) | B32: 0.154 | C32: % | D32: AGGIORNATO da 13,37% (v1) a 15,4% (RGS 2024) | E32: RGS Rapporto 26/2025
A33: Spesa PAYG/PIL picco 2040 | B33: 0.171 | C33: % | D33: Picco RGS 17,1% al 2040 (NUOVO nel modello) | E33: RGS 26/2025 + Ageing Report 2024
A34: Spesa PAYG/PIL 2070 | B34: 0.14 | C34: % | D34: Rientro RGS condizionato a produttività+migrazione | E34: RGS 26/2025 — scenario base
A35: Anno picco spesa/PIL | B35: 2040 | C35: anno | D35: Determina la traiettoria a U-rovesciata | E35: RGS
A37: PILASTRO 0 — SUSSIDIO UNIVERSALE
A38: P0 base mensile (B) | B38: 650 | C38: €/mese | D38: Sopra soglia povertà ISTAT (€598 Nord) | E38: Calibrazione propria
A39: Aliquota di taper (t) | B39: =B38/B40 -> 0.52 | C39: % | D39: EMRT 52% nella zona di taper | E39: Ingles-Stewart 2017 (Australia)
A40: Cap reddito totale | B40: 1250 | C40: €/mese | D40: P0=0 oltre B/t = 1.250 | E40: B/t
A41: Franchigia patrimoniale | B41: 50000 | C41: € | D41: Patrimonio escluso dal deemed rate | E41: Modello AU/UK
A42: Deemed rate | B42: 0.045 | C42: % | D42: Rendimento figurativo (era 7,8% AU post-2017, ridotto) | E42: Cilibrato vs AU
A43: P0 medio mensile a regime (calcolato) | B43: =MAX(0,B22-B23*(B45*B17*((1+B49)^B50-1)/B48)*B41/12) -> 0.002 | C43: €/mese | D43: Si aggiorna se cambi r_fondi | E43: Derivato
A44: Anni per phase-in P0 (sostituz. PAYG) | B44: 35 | C44: anni | D44: RIDOTTO 50→35: tasso flusso nuovi pensionati ~3,7%/anno | E44: Bilanciato su 600k/16 mln
A45: Nuovi pensionati l'anno (flusso) | B45: 600000 | C45: persone/anno | D45: Stima INPS — base per Leva F corretta | E45: INPS Flussi Pensionamento
A47: PILASTRO 2 E BRDP — biforcazione contributiva
A48: Quota biforcazione Fase I (totale) | B48: 0.06 | C48: % | D48: Anni 1-10: 6% totale di cui 2 BRDP + 4 P2 | E48: Calibrazione propria
...

Sheet Modello
A1: MODELLO — PROIEZIONE ANNO PER ANNO (v2, 30 anni 2026-2055)
A2: Tutti i valori in termini reali (prezzi 2026). Flussi positivi = risparmi/entrate per lo Stato; negativi = costi/fabbisogno.
U3: LEVA F: formula calibrata su t=0..26 (errore <0.003 mld). Anni t=27-29 divergono dal v2 originale (~2-8 mld) per un cambio di logica non ricostruibile nei dati originali. Il v2 originale mostra ΔU costante a 3.535 mld/anno per t=28,29. Aggiornare f0,f1 in Parametri per ricalibrazione.
A4: Anno | B4: t | C4: Pensioni vigenti (mln) | D4: Occupati L1 (mln) | E4: Att/Pens | F4: PIL reale (€mld) | G4: Salario medio (€) | H4: Spesa PAYG SQ (€mld) | I4: Spesa PAYG %PIL (RGS) | J4: Spesa rif. (€mld) | K4: Spesa rif./PIL | L4: %Lav in P2 | M4: Lav. in P2 (mln) | N4: Leva A (€mld) | O4: Leva B (€mld) | P4: Leva C (€mld) | Q4: Leva D gap (€mld) | R4: BRDP emessi (€mld) | S4: BRDP esterni (€mld) | T4: Leva E (€mld) | U4: Leva F CORRETTA | V4: Leva G (€mld) | W4: Leva H (€mld) | X4: Leva I (€mld) | Y4: Leva J (€mld) | Z4: Saldo annuo (€mld) | AA4: Saldo cum. (€mld) | AB4: Debito tr./PIL
A5: =Parametri!$B$6+B5 -> 2026 | B5: 0 | C5: =Parametri!$B$9 -> 21.3 | D5: =Parametri!$B$13 -> 17.5 | E5: =D5/C5 -> 0.82159624 | F5: =Parametri!$B$19 -> 2184 | G5: =Parametri!$B$21 -> 26000 | H5: =F5*I5 -> 336.336 | I5: =IF(B5<=(Parametri!$B$35-Parametri!$B$6),Parametri!$B$32+(Parametri!$B$33-Parametri!$B$32)*B5/(Parametri!$B$35-Parametri!$B$6),Parametri!$B$33+(Parametri!$B$34-Parametri!$B$33)*(B5-(Parametri!$B$35-Parametri!$B$6))/(2070-Parametri!$B$35)) -> 0.154 | J5: =H5-U5 -> 335.31101 | K5: =J5/F5 -> 0.15353068 | L5: =IF(B5<=5,Parametri!$B$55+(Parametri!$B$56-Parametri!$B$55)/5*B5,MIN(Parametri!$B$57,Parametri!$B$56+(Parametri!$B$57-Parametri!$B$56)/24*(B5-5))) -> 0.33 | M5: =L5*D5 -> 5.775 | N5: =IF(B5<Parametri!$B$72,Parametri!$B$71*Parametri!$B$70*Parametri!$B$69/Parametri!$B$72,0) -> 2.44 | O5: =IF(B5<10,Parametri!$B$50,IF(B5<20,Parametri!$B$53,Parametri!$B$54))*M5*G5*Parametri!$B$68/1000 -> 1.62162 | P5: =MIN(Parametri!$B$77+Parametri!$B$78, Parametri!$B$77+Parametri!$B$78*(B5+1)/Parametri!$B$79) -> 4.1 | Q5: =-IF(B5<10,Parametri!$B$48,IF(B5<20,Parametri!$B$51,Parametri!$B$54))*M5*G5/1000 -> -9.009 | R5: =IF(B5<10,Parametri!$B$49,IF(B5<20,Parametri!$B$52,0))*M5*G5/1000 -> 3.003 | S5: 0 | T5: =-(Parametri!$B$82*(Parametri!$B$83*Parametri!$B$86+Parametri!$B$84*Parametri!$B$87+Parametri!$B$85*Parametri!$B$88)/1000000000)*MIN(B5+1,Parametri!$B$89) -> -0.58745 | U5: =Parametri!$B$45*Parametri!$B$92*13/1000000000*((B5+1)*Parametri!$B$117+B5*(B5+1)/2*Parametri!$B$118) -> 1.0249902 | V5: =IF(B5>=Parametri!$B$99-1,Parametri!$B$98,0) -> 6 | W5: =IF(B5>=Parametri!$B$101-1,Parametri!$B$100,0) -> 0 | X5: =IF(B5>=Parametri!$B$103-1,Parametri!$B$102,0) -> 0 | Y5: =IF(B5>=Parametri!$B$105-1,Parametri!$B$104,0) -> 1 | Z5: =N5+O5+P5+Q5+T5+U5+V5+W5+X5+Y5 -> 6.5901602 | AA5: =Z5 -> 6.5901602 | AB5: =-AA5/F5 -> -0.0030174726
A6: =Parametri!$B$6+B6 -> 2027 | B6: 1 | C6: =C5*(1+Parametri!$B$14) -> 21.513 | D6: =D5*(1+Parametri!$B$15)+Parametri!$B$18*(1-Parametri!$B$15)^B5 -> 17.5285 | E6: =D6/C6 -> 0.81478641 | F6: =F5*(1+Parametri!$B$20) -> 2201.472 | G6: =G5*(1+Parametri!$B$22) -> 26052 | H6: =F6*I6 -> 341.6999 | I6: =IF(B6<=(Parametri!$B$35-Parametri!$B$6),Parametri!$B$32+(Parametri!$B$33-Parametri!$B$32)*B6/(Parametri!$B$35-Parametri!$B$6),Parametri!$B$33+(Parametri!$B$34-Parametri!$B$33)*(B6-(Parametri!$B$35-Parametri!$B$6))/(2070-Parametri!$B$35)) -> 0.15521429 | J6: =H6-U6 -> 339.45796 | K6: =J6/F6 -> 0.1541959 | L6: =IF(B6<=5,Parametri!$B$55+(Parametri!$B$56-Parametri!$B$55)/5*B6,MIN(Parametri!$B$57,Parametri!$B$56+(Parametri!$B$57-Parametri!$B$56)/24*(B6-5))) -> 0.384 | M6: =L6*D6 -> 6.730944 | N6: =IF(B6<Parametri!$B$72,Parametri!$B$71*Parametri!$B$70*Parametri!$B$69/Parametri!$B$72,0) -> 2.44 | O6: =IF(B6<10,Parametri!$B$50,IF(B6<20,Parametri!$B$53,Parametri!$B$54))*M6*G6*Parametri!$B$68/1000 -> 1.8938292 | P6: =MIN(Parametri!$B$77+Parametri!$B$78, Parametri!$B$77+Parametri!$B$78*(B6+1)/Parametri!$B$79) -> 4.7 | Q6: =-IF(B6<10,Parametri!$B$48,IF(B6<20,Parametri!$B$51,Parametri!$B$54))*M6*G6/1000 -> -10.521273 | R6: =IF(B6<10,Parametri!$B$49,IF(B6<20,Parametri!$B$52,0))*M6*G6/1000 -> 3.5070911 | S6: 0 | T6: =-(Parametri!$B$82*(Parametri!$B$83*Parametri!$B$86+Parametri!$B$84*Parametri!$B$87+Parametri!$B$85*Parametri!$B$88)/1000000000)*MIN(B6+1,Parametri!$B$89) -> -1.1749 | U6: =Parametri!$B$45*Parametri!$B$92*13/1000000000*((B6+1)*Parametri!$B$117+B6*(B6+1)/2*Parametri!$B$118) -> 2.2419423 | V6: =IF(B6>=Parametri!$B$99-1,Parametri!$B$98,0) -> 6 | W6: =IF(B6>=Parametri!$B$101-1,Parametri!$B$100,0) -> 5 | X6: =IF(B6>=Parametri!$B$103-1,Parametri!$B$102,0) -> 2.75 | Y6: =IF(B6>=Parametri!$B$105-1,Parametri!$B$104,0) -> 1 | Z6: =N6+O6+P6+Q6+T6+U6+V6+W6+X6+Y6 -> 14.329598 | AA6: =AA5+Z6 -> 20.919758 | AB6: =-AA6/F6 -> -0.009502623
A7: =Parametri!$B$6+B7 -> 2028 | B7: 2 | C7: =C6*(1+Parametri!$B$14) -> 21.72813 | D7: =D6*(1+Parametri!$B$15)+Parametri!$B$18*(1-Parametri!$B$15)^B6 -> 17.557437 | E7: =D7/C7 -> 0.80805101 | F7: =F6*(1+Parametri!$B$20) -> 2219.0838 | G7: =G6*(1+Parametri!$B$22) -> 26104.104 | H7: =F7*I7 -> 347.1281 | I7: =IF(B7<=(Parametri!$B$35-Parametri!$B$6),Parametri!$B$32+(Parametri!$B$33-Parametri!$B$32)*B7/(Parametri!$B$35-Parametri!$B$6),Parametri!$B$33+(Parametri!$B$34-Parametri!$B$33)*(B7-(Parametri!$B$35-Parametri!$B$6))/(2070-Parametri!$B$35)) -> 0.15642857 | J7: =H7-U7 -> 343.47725 | K7: =J7/F7 -> 0.15478336 | L7: =IF(B7<=5,Parametri!$B$55+(Parametri!$B$56-Parametri!$B$55)/5*B7,MIN(Parametri!$B$57,Parametri!$B$56+(Parametri!$B$57-Parametri!$B$56)/24*(B7-5))) -> 0.438 | M7: =L7*D7 -> 7.6901576 | N7: =IF(B7<Parametri!$B$72,Parametri!$B$71*Parametri!$B$70*Parametri!$B$69/Parametri!$B$72,0) -> 2.44 | O7: =IF(B7<10,Parametri!$B$50,IF(B7<20,Parametri!$B$53,Parametri!$B$54))*M7*G7*Parametri!$B$68/1000 -> 2.1680425 | P7: =MIN(Parametri!$B$77+Parametri!$B$78, Parametri!$B$77+Parametri!$B$78*(B7+1)/Parametri!$B$79) -> 5.3 | Q7: =-IF(B7<10,Parametri!$B$48,IF(B7<20,Parametri!$B$51,Parametri!$B$54))*M7*G7/1000 -> -12.04468 | R7: =IF(B7<10,Parametri!$B$49,IF(B7<20,Parametri!$B$52,0))*M7*G7/1000 -> 4.0148935 | S7: 0 | T7: =-(Parametri!$B$82*(Parametri!$B$83*Parametri!$B$86+Parametri!$B$84*Parametri!$B$87+Parametri!$B$85*Parametri!$B$88)/1000000000)*MIN(B7+1,Parametri!$B$89) -> -1.76235 | U7: =Parametri!$B$45*Parametri!$B$92*13/1000000000*((B7+1)*Parametri!$B$117+B7*(B7+1)/2*Parametri!$B$118) -> 3.6508563 | V7: =IF(B7>=Parametri!$B$99-1,Parametri!$B$98,0) -> 6 | W7: =IF(B7>=Parametri!$B$101-1,Parametri!$B$100,0) -> 5 | X7: =IF(B7>=Parametri!$B$103-1,Parametri!$B$102,0) -> 2.75 | Y7: =IF(B7>=Parametri!$B$105-1,Parametri!$B$104,0) -> 1 | Z7: =N7+O7+P7+Q7+T7+U7+V7+W7+X7+Y7 -> 14.501868 | AA7: =AA6+Z7 -> 35.421627 | AB7: =-AA7/F7 -> -0.015962276
A8: =Parametri!$B$6+B8 -> 2029 | B8: 3 | C8: =C7*(1+Parametri!$B$14) -> 21.945411 | D8: =D7*(1+Parametri!$B$15)+Parametri!$B$18*(1-Parametri!$B$15)^B7 -> 17.586813 | E8: =D8/C8 -> 0.80138909 | F8: =F7*(1+Parametri!$B$20) -> 2236.8364 | G8: =G7*(1+Parametri!$B$22) -> 26156.312 | H8: =F8*I8 -> 352.62129 | I8: =IF(B8<=(Parametri!$B$35-Parametri!$B$6),Parametri!$B$32+(Parametri!$B$33-Parametri!$B$32)*B8/(Parametri!$B$35-Parametri!$B$6),Parametri!$B$33+(Parametri!$B$34-Parametri!$B$33)*(B8-(Parametri!$B$35-Parametri!$B$6))/(2070-Parametri!$B$35)) -> 0.15764286 | J8: =H8-U8 -> 347.36956 | K8: =J8/F8 -> 0.15529502 | L8: =IF(B8<=5,Parametri!$B$55+(Parametri!$B$56-Parametri!$B$55)/5*B8,MIN(Parametri!$B$57,Parametri!$B$56+(Parametri!$B$57-Parametri!$B$56)/24*(B8-5))) -> 0.492 | M8: =L8*D8 -> 8.6527121 | N8: =IF(B8<Parametri!$B$72,Parametri!$B$71*Parametri!$B$70*Parametri!$B$69/Parametri!$B$72,0) -> 0 | O8: =IF(B8<10,Parametri!$B$50,IF(B8<20,Parametri!$B$53,Parametri!$B$54))*M8*G8*Parametri!$B$68/1000 -> 2.4442888 | P8: =MIN(Parametri!$B$77+Parametri!$B$78, Parametri!$B$77+Parametri!$B$78*(B8+1)/Parametri!$B$79) -> 5.9 | Q8: =-IF(B8<10,Parametri!$B$48,IF(B8<20,Parametri!$B$51,Parametri!$B$54))*M8*G8/1000 -> -13.579382 | R8: =IF(B8<10,Parametri!$B$49,IF(B8<20,Parametri!$B$52,0))*M8*G8/1000 -> 4.5264608 | S8: 0 | T8: =-(Parametri!$B$82*(Parametri!$B$83*Parametri!$B$86+Parametri!$B$84*Parametri!$B$87+Parametri!$B$85*Parametri!$B$88)/1000000000)*MIN(B8+1,Parametri!$B$89) -> -2.3498 | U8: =Parametri!$B$45*Parametri!$B$92*13/1000000000*((B8+1)*Parametri!$B$117+B8*(B8+1)/2*Parametri!$B$118) -> 5.2517322 | V8: =IF(B8>=Parametri!$B$99-1,Parametri!$B$98,0) -> 6 | W8: =IF(B8>=Parametri!$B$101-1,Parametri!$B$100,0) -> 5 | X8: =IF(B8>=Parametri!$B$103-1,Parametri!$B$102,0) -> 2.75 | Y8: =IF(B8>=Parametri!$B$105-1,Parametri!$B$104,0) -> 1 | Z8: =N8+O8+P8+Q8+T8+U8+V8+W8+X8+Y8 -> 12.416839 | AA8: =AA7+Z8 -> 47.838465 | AB8: =-AA8/F8 -> -0.021386662
A9: =Parametri!$B$6+B9 -> 2030 | B9: 4 | C9: =C8*(1+Parametri!$B$14) -> 22.164865 | D9: =D8*(1+Parametri!$B$15)+Parametri!$B$18*(1-Parametri!$B$15)^B8 -> 17.616628 | E9: =D9/C9 -> 0.79479968 | F9: =F8*(1+Parametri!$B$20) -> 2254.7311 | G9: =G8*(1+Parametri!$B$22) -> 26208.625 | H9: =F9*I9 -> 358.18015 | I9: =IF(B9<=(Parametri!$B$35-Parametri!$B$6),Parametri!$B$32+(Parametri!$B$33-Parametri!$B$32)*B9/(Parametri!$B$35-Parametri!$B$6),Parametri!$B$33+(Parametri!$B$34-Parametri!$B$33)*(B9-(Parametri!$B$35-Parametri!$B$6))/(2070-Parametri!$B$35)) -> 0.15885714 | J9: =H9-U9 -> 351.13558 | K9: =J9/F9 -> 0.15573279 | L9: =IF(B9<=5,Parametri!$B$55+(Parametri!$B$56-Parametri!$B$55)/5*B9,MIN(Parametri!$B$57,Parametri!$B$56+(Parametri!$B$57-Parametri!$B$56)/24*(B9-5))) -> 0.546 | M9: =L9*D9 -> 9.6186788 | N9: =IF(B9<Parametri!$B$72,Parametri!$B$71*Parametri!$B$70*Parametri!$B$69/Parametri!$B$72,0) -> 0 | O9: =IF(B9<10,Parametri!$B$50,IF(B9<20,Parametri!$B$53,Parametri!$B$54))*M9*G9*Parametri!$B$68/1000 -> 2.7225973 | P9: =MIN(Parametri!$B$77+Parametri!$B$78, Parametri!$B$77+Parametri!$B$78*(B9+1)/Parametri!$B$79) -> 6.5 | Q9: =-IF(B9<10,Parametri!$B$48,IF(B9<20,Parametri!$B$51,Parametri!$B$54))*M9*G9/1000 -> -15.125541 | R9: =IF(B9<10,Parametri!$B$49,IF(B9<20,Parametri!$B$52,0))*M9*G9/1000 -> 5.0418469 | S9: 0 | T9: =-(Parametri!$B$82*(Parametri!$B$83*Parametri!$B$86+Parametri!$B$84*Parametri!$B$87+Parametri!$B$85*Parametri!$B$88)/1000000000)*MIN(B9+1,Parametri!$B$89) -> -2.93725 | U9: =Parametri!$B$45*Parametri!$B$92*13/1000000000*((B9+1)*Parametri!$B$117+B9*(B9+1)/2*Parametri!$B$118) -> 7.04457 | V9: =IF(B9>=Parametri!$B$99-1,Parametri!$B$98,0) -> 6 | W9: =IF(B9>=Parametri!$B$101-1,Parametri!$B$100,0) -> 5 | X9: =IF(B9>=Parametri!$B$103-1,Parametri!$B$102,0) -> 2.75 | Y9: =IF(B9>=Parametri!$B$105-1,Parametri!$B$104,0) -> 1 | Z9: =N9+O9+P9+Q9+T9+U9+V9+W9+X9+Y9 -> 12.954377 | AA9: =AA8+Z9 -> 60.792842 | AB9: =-AA9/F9 -> -0.026962346
A10: =Parametri!$B$6+B10 -> 2031 | B10: 5 | C10: =C9*(1+Parametri!$B$14) -> 22.386514 | D10: =D9*(1+Parametri!$B$15)+Parametri!$B$18*(1-Parametri!$B$15)^B9 -> 17.646882 | E10: =D10/C10 -> 0.78828183 | F10: =F9*(1+Parametri!$B$20) -> 2272.769 | G10: =G9*(1+Parametri!$B$22) -> 26261.042 | H10: =F10*I10 -> 363.80538 | I10: =IF(B10<=(Parametri!$B$35-Parametri!$B$6),Parametri!$B$32+(Parametri!$B$33-Parametri!$B$32)*B10/(Parametri!$B$35-Parametri!$B$6),Parametri!$B$33+(Parametri!$B$34-Parametri!$B$33)*(B10-(Parametri!$B$35-Parametri!$B$6))/(2070-Parametri!$B$35)) -> 0.16007143 | J10: =H10-U10 -> 354.77601 | K10: =J10/F10 -> 0.15609858 | L10: =IF(B10<=5,Parametri!$B$55+(Parametri!$B$56-Parametri!$B$55)/5*B10,MIN(Parametri!$B$57,Parametri!$B$56+(Parametri!$B$57-Parametri!$B$56)/24*(B10-5))) -> 0.6 | M10: =L10*D10 -> 10.588129 | N10: =IF(B10<Parametri!$B$72,Parametri!$B$71*Parametri!$B$70*Parametri!$B$69/Parametri!$B$72,0) -> 0 | O10: =IF(B10<10,Parametri!$B$50,IF(B10<20,Parametri!$B$53,Parametri!$B$54))*M10*G10*Parametri!$B$68/1000 -> 3.0029973 | P10: =MIN(Parametri!$B$77+Parametri!$B$78, Parametri!$B$77+Parametri!$B$78*(B10+1)/Parametri!$B$79) -> 7.1 | Q10: =-IF(B10<10,Parametri!$B$48,IF(B10<20,Parametri!$B$51,Parametri!$B$54))*M10*G10/1000 -> -16.683319 | R10: =IF(B10<10,Parametri!$B$49,IF(B10<20,Parametri!$B$52,0))*M10*G10/1000 -> 5.5611062 | S10: 0 | T10: =-(Parametri!$B$82*(Parametri!$B$83*Parametri!$B$86+Parametri!$B$84*Parametri!$B$87+Parametri!$B$85*Parametri!$B$88)/1000000000)*MIN(B10+1,Parametri!$B$89) -> -2.93725 | U10: =Parametri!$B$45*Parametri!$B$92*13/1000000000*((B10+1)*Parametri!$B$117+B10*(B10+1)/2*Parametri!$B$118) -> 9.0293697 | V10: =IF(B10>=Parametri!$B$99-1,Parametri!$B$98,0) -> 6 | W10: =IF(B10>=Parametri!$B$101-1,Parametri!$B$100,0) -> 5 | X10: =IF(B10>=Parametri!$B$103-1,Parametri!$B$102,0) -> 2.75 | Y10: =IF(B10>=Parametri!$B$105-1,Parametri!$B$104,0) -> 1 | Z10: =N10+O10+P10+Q10+T10+U10+V10+W10+X10+Y10 -> 14.261798 | AA10: =AA9+Z10 -> 75.054641 | AB10: =-AA10/F10 -> -0.033023436
A11: =Parametri!$B$6+B11 -> 2032 | B11: 6 | C11: =C10*(1+Parametri!$B$14) -> 22.610379 | D11: =D10*(1+Parametri!$B$15)+Parametri!$B$18*(1-Parametri!$B$15)^B10 -> 17.677577 | E11: =D11/C11 -> 0.78183461 | F11: =F10*(1+Parametri!$B$20) -> 2290.9511 | G11: =G10*(1+Parametri!$B$22) -> 26313.564 | H11: =F11*I11 -> 369.49769 | I11: =IF(B11<=(Parametri!$B$35-Parametri!$B$6),Parametri!$B$32+(Parametri!$B$33-Parametri!$B$32)*B11/(Parametri!$B$35-Parametri!$B$6),Parametri!$B$33+(Parametri!$B$34-Parametri!$B$33)*(B11-(Parametri!$B$35-Parametri!$B$6))/(2070-Parametri!$B$35)) -> 0.16128571 | J11: =H11-U11 -> 358.29156 | K11: =J11/F11 -> 0.15639424 | L11: =IF(B11<=5,Parametri!$B$55+(Parametri!$B$56-Parametri!$B$55)/5*B11,MIN(Parametri!$B$57,Parametri!$B$56+(Parametri!$B$57-Parametri!$B$56)/24*(B11-5))) -> 0.61666667 | M11: =L11*D11 -> 10.901172 | N11: =IF(B11<Parametri!$B$72,Parametri!$B$71*Parametri!$B$70*Parametri!$B$69/Parametri!$B$72,0) -> 0 | O11: =IF(B11<10,Parametri!$B$50,IF(B11<20,Parametri!$B$53,Parametri!$B$54))*M11*G11*Parametri!$B$68/1000 -> 3.097966 | P11: =MIN(Parametri!$B$77+Parametri!$B$78, Parametri!$B$77+Parametri!$B$78*(B11+1)/Parametri!$B$79) -> 7.7 | Q11: =-IF(B11<10,Parametri!$B$48,IF(B11<20,Parametri!$B$51,Parametri!$B$54))*M11*G11/1000 -> -17.210922 | R11: =IF(B11<10,Parametri!$B$49,IF(B11<20,Parametri!$B$52,0))*M11*G11/1000 -> 5.736974 | S11: 0 | T11: =-(Parametri!$B$82*(Parametri!$B$83*Parametri!$B$86+Parametri!$B$84*Parametri!$B$87+Parametri!$B$85*Parametri!$B$88)/1000000000)*MIN(B11+1,Parametri!$B$89) -> -2.93725 | U11: =Parametri!$B$45*Parametri!$B$92*13/1000000000*((B11+1)*Parametri!$B$117+B11*(B11+1)/2*Parametri!$B$118) -> 11.206131 | V11: =IF(B11>=Parametri!$B$99-1,Parametri!$B$98,0) -> 6 | W11: =IF(B11>=Parametri!$B$101-1,Parametri!$B$100,0) -> 5 | X11: =IF(B11>=Parametri!$B$103-1,Parametri!$B$102,0) -> 2.75 | Y11: =IF(B11>=Parametri!$B$105-1,Parametri!$B$104,0) -> 1 | Z11: =N11+O11+P11+Q11+T11+U11+V11+W11+X11+Y11 -> 16.605925 | AA11: =AA10+Z11 -> 91.660566 | AB11: =-AA11/F11 -> -0.04000983
A12: =Parametri!$B$6+B12 -> 2033 | B12: 7 | C12: =C11*(1+Parametri!$B$14) -> 22.836483 | D12: =D11*(1+Parametri!$B$15)+Parametri!$B$18*(1-Parametri!$B$15)^B11 -> 17.708713 | E12: =D12/C12 -> 0.7754571 | F12: =F11*(1+Parametri!$B$20) -> 2309.2787 | G12: =G11*(1+Parametri!$B$22) -> 26366.191 | H12: =F12*I12 -> 375.2578 | I12: =IF(B12<=(Parametri!$B$35-Parametri!$B$6),Parametri!$B$32+(Parametri!$B$33-Parametri!$B$32)*B12/(Parametri!$B$35-Parametri!$B$6),Parametri!$B$33+(Parametri!$B$34-Parametri!$B$33)*(B12-(Parametri!$B$35-Parametri!$B$6))/(2070-Parametri!$B$35)) -> 0.1625 | J12: =H12-U12 -> 361.68294 | K12: =J12/F12 -> 0.1566216 | L12: =IF(B12<=5,Parametri!$B$55+(Parametri!$B$56-Parametri!$B$55)/5*B12,MIN(Parametri!$B$57,Parametri!$B$56+(Parametri!$B$57-Parametri!$B$56)/24*(B12-5))) -> 0.63333333 | M12: =L12*D12 -> 11.215518 | N12: =IF(B12<Parametri!$B$72,Parametri!$B$71*Parametri!$B$70*Parametri!$B$69/Parametri!$B$72,0) -> 0 | O12: =IF(B12<10,Parametri!$B$50,IF(B12<20,Parametri!$B$53,Parametri!$B$54))*M12*G12*Parametri!$B$68/1000 -> 3.1936734 | P12: =MIN(Parametri!$B$77+Parametri!$B$78, Parametri!$B$77+Parametri!$B$78*(B12+1)/Parametri!$B$79) -> 8.3 | Q12: =-IF(B12<10,Parametri!$B$48,IF(B12<20,Parametri!$B$51,Parametri!$B$54))*M12*G12/1000 -> -17.74263 | R12: =IF(B12<10,Parametri!$B$49,IF(B12<20,Parametri!$B$52,0))*M12*G12/1000 -> 5.9142099 | S12: 0 | T12: =-(Parametri!$B$82*(Parametri!$B$83*Parametri!$B$86+Parametri!$B$84*Parametri!$B$87+Parametri!$B$85*Parametri!$B$88)/1000000000)*MIN(B12+1,Parametri!$B$89) -> -2.93725 | U12: =Parametri!$B$45*Parametri!$B$92*13/1000000000*((B12+1)*Parametri!$B$117+B12*(B12+1)/2*Parametri!$B$118) -> 13.574855 | V12: =IF(B12>=Parametri!$B$99-1,Parametri!$B$98,0) -> 6 | W12: =IF(B12>=Parametri!$B$101-1,Parametri!$B$100,0) -> 5 | X12: =IF(B12>=Parametri!$B$103-1,Parametri!$B$102,0) -> 2.75 | Y12: =IF(B12>=Parametri!$B$105-1,Parametri!$B$104,0) -> 1 | Z12: =N12+O12+P12+Q12+T12+U12+V12+W12+X12+Y12 -> 19.138648 | AA12: =AA11+Z12 -> 110.79921 | AB12: =-AA12/F12 -> -0.047980009
A13: =Parametri!$B$6+B13 -> 2034 | B13: 8 | C13: =C12*(1+Parametri!$B$14) -> 23.064848 | D13: =D12*(1+Parametri!$B$15)+Parametri!$B$18*(1-Parametri!$B$15)^B12 -> 17.740291 | E13: =D13/C13 -> 0.76914839 | F13: =F12*(1+Parametri!$B$20) -> 2327.753 | G13: =G12*(1+Parametri!$B$22) -> 26418.924 | H13: =F13*I13 -> 381.08642 | I13: =IF(B13<=(Parametri!$B$35-Parametri!$B$6),Parametri!$B$32+(Parametri!$B$33-Parametri!$B$32)*B13/(Parametri!$B$35-Parametri!$B$6),Parametri!$B$33+(Parametri!$B$34-Parametri!$B$33)*(B13-(Parametri!$B$35-Parametri!$B$6))/(2070-Parametri!$B$35)) -> 0.16371429 | J13: =H13-U13 -> 364.95088 | K13: =J13/F13 -> 0.15678248 | L13: =IF(B13<=5,Parametri!$B$55+(Parametri!$B$56-Parametri!$B$55)/5*B13,MIN(Parametri!$B$57,Parametri!$B$56+(Parametri!$B$57-Parametri!$B$56)/24*(B13-5))) -> 0.65 | M13: =L13*D13 -> 11.531189 | N13: =IF(B13<Parametri!$B$72,Parametri!$B$71*Parametri!$B$70*Parametri!$B$69/Parametri!$B$72,0) -> 0 | O13: =IF(B13<10,Parametri!$B$50,IF(B13<20,Parametri!$B$53,Parametri!$B$54))*M13*G13*Parametri!$B$68/1000 -> 3.2901293 | P13: =MIN(Parametri!$B$77+Parametri!$B$78, Parametri!$B$77+Parametri!$B$78*(B13+1)/Parametri!$B$79) -> 8.9 | Q13: =-IF(B13<10,Parametri!$B$48,IF(B13<20,Parametri!$B$51,Parametri!$B$54))*M13*G13/1000 -> -18.278496 | R13: =IF(B13<10,Parametri!$B$49,IF(B13<20,Parametri!$B$52,0))*M13*G13/1000 -> 6.092832 | S13: 0 | T13: =-(Parametri!$B$82*(Parametri!$B$83*Parametri!$B$86+Parametri!$B$84*Parametri!$B$87+Parametri!$B$85*Parametri!$B$88)/1000000000)*MIN(B13+1,Parametri!$B$89) -> -2.93725 | U13: =Parametri!$B$45*Parametri!$B$92*13/1000000000*((B13+1)*Parametri!$B$117+B13*(B13+1)/2*Parametri!$B$118) -> 16.13554 | V13: =IF(B13>=Parametri!$B$99-1,Parametri!$B$98,0) -> 6 | W13: =IF(B13>=Parametri!$B$101-1,Parametri!$B$100,0) -> 5 | X13: =IF(B13>=Parametri!$B$103-1,Parametri!$B$102,0) -> 2.75 | Y13: =IF(B13>=Parametri!$B$105-1,Parametri!$B$104,0) -> 1 | Z13: =N13+O13+P13+Q13+T13+U13+V13+W13+X13+Y13 -> 21.859923 | AA13: =AA12+Z13 -> 132.65914 | AB13: =-AA13/F13 -> -0.056990213
A14: =Parametri!$B$6+B14 -> 2035 | B14: 9 | C14: =C13*(1+Parametri!$B$14) -> 23.295496 | D14: =D13*(1+Parametri!$B$15)+Parametri!$B$18*(1-Parametri!$B$15)^B13 -> 17.772311 | E14: =D14/C14 -> 0.7629076 | F14: =F13*(1+Parametri!$B$20) -> 2346.375 | G14: =G13*(1+Parametri!$B$22) -> 26471.762 | H14: =F14*I14 -> 386.98428 | I14: =IF(B14<=(Parametri!$B$35-Parametri!$B$6),Parametri!$B$32+(Parametri!$B$33-Parametri!$B$32)*B14/(Parametri!$B$35-Parametri!$B$6),Parametri!$B$33+(Parametri!$B$34-Parametri!$B$33)*(B14-(Parametri!$B$35-Parametri!$B$6))/(2070-Parametri!$B$35)) -> 0.16492857 | J14: =H14-U14 -> 368.09609 | K14: =J14/F14 -> 0.15687863 | L14: =IF(B14<=5,Parametri!$B$55+(Parametri!$B$56-Parametri!$B$55)/5*B14,MIN(Parametri!$B$57,Parametri!$B$56+(Parametri!$B$57-Parametri!$B$56)/24*(B14-5))) -> 0.66666667 | M14: =L14*D14 -> 11.848207 | N14: =IF(B14<Parametri!$B$72,Parametri!$B$71*Parametri!$B$70*Parametri!$B$69/Parametri!$B$72,0) -> 0 | O14: =IF(B14<10,Parametri!$B$50,IF(B14<20,Parametri!$B$53,Parametri!$B$54))*M14*G14*Parametri!$B$68/1000 -> 3.3873436 | P14: =MIN(Parametri!$B$77+Parametri!$B$78, Parametri!$B$77+Parametri!$B$78*(B14+1)/Parametri!$B$79) -> 9.5 | Q14: =-IF(B14<10,Parametri!$B$48,IF(B14<20,Parametri!$B$51,Parametri!$B$54))*M14*G14/1000 -> -18.818575 | R14: =IF(B14<10,Parametri!$B$49,IF(B14<20,Parametri!$B$52,0))*M14*G14/1000 -> 6.2728585 | S14: 0 | T14: =-(Parametri!$B$82*(Parametri!$B$83*Parametri!$B$86+Parametri!$B$84*Parametri!$B$87+Parametri!$B$85*Parametri!$B$88)/1000000000)*MIN(B14+1,Parametri!$B$89) -> -2.93725 | U14: =Parametri!$B$45*Parametri!$B$92*13/1000000000*((B14+1)*Parametri!$B$117+B14*(B14+1)/2*Parametri!$B$118) -> 18.888187 | V14: =IF(B14>=Parametri!$B$99-1,Parametri!$B$98,0) -> 6 | W14: =IF(B14>=Parametri!$B$101-1,Parametri!$B$100,0) -> 5 | X14: =IF(B14>=Parametri!$B$103-1,Parametri!$B$102,0) -> 2.75 | Y14: =IF(B14>=Parametri!$B$105-1,Parametri!$B$104,0) -> 1 | Z14: =N14+O14+P14+Q14+T14+U14+V14+W14+X14+Y14 -> 24.769706 | AA14: =AA13+Z14 -> 157.42884 | AB14: =-AA14/F14 -> -0.067094494
A15: =Parametri!$B$6+B15 -> 2036 | B15: 10 | C15: =C14*(1+Parametri!$B$14) -> 23.528451 | D15: =D14*(1+Parametri!$B$15)+Parametri!$B$18*(1-Parametri!$B$15)^B14 -> 17.804775 | E15: =D15/C15 -> 0.75673384 | F15: =F14*(1+Parametri!$B$20) -> 2365.146 | G15: =G14*(1+Parametri!$B$22) -> 26524.705 | H15: =F15*I15 -> 392.95211 | I15: =IF(B15<=(Parametri!$B$35-Parametri!$B$6),Parametri!$B$32+(Parametri!$B$33-Parametri!$B$32)*B15/(Parametri!$B$35-Parametri!$B$6),Parametri!$B$33+(Parametri!$B$34-Parametri!$B$33)*(B15-(Parametri!$B$35-Parametri!$B$6))/(2070-Parametri!$B$35)) -> 0.16614286 | J15: =H15-U15 -> 371.11932 | K15: =J15/F15 -> 0.1569118 | L15: =IF(B15<=5,Parametri!$B$55+(Parametri!$B$56-Parametri!$B$55)/5*B15,MIN(Parametri!$B$57,Parametri!$B$56+(Parametri!$B$57-Parametri!$B$56)/24*(B15-5))) -> 0.68333333 | M15: =L15*D15 -> 12.166596 | N15: =IF(B15<Parametri!$B$72,Parametri!$B$71*Parametri!$B$70*Parametri!$B$69/Parametri!$B$72,0) -> 0 | O15: =IF(B15<10,Parametri!$B$50,IF(B15<20,Parametri!$B$53,Parametri!$B$54))*M15*G15*Parametri!$B$68/1000 -> 5.2279892 | P15: =MIN(Parametri!$B$77+Parametri!$B$78, Parametri!$B$77+Parametri!$B$78*(B15+1)/Parametri!$B$79) -> 10.1 | Q15: =-IF(B15<10,Parametri!$B$48,IF(B15<20,Parametri!$B$51,Parametri!$B$54))*M15*G15/1000 -> -19.362923 | R15: =IF(B15<10,Parametri!$B$49,IF(B15<20,Parametri!$B$52,0))*M15*G15/1000 -> 0 | S15: 0 | T15: =-(Parametri!$B$82*(Parametri!$B$83*Parametri!$B$86+Parametri!$B$84*Parametri!$B$87+Parametri!$B$85*Parametri!$B$88)/1000000000)*MIN(B15+1,Parametri!$B$89) -> -2.93725 | U15: =Parametri!$B$45*Parametri!$B$92*13/1000000000*((B15+1)*Parametri!$B$117+B15*(B15+1)/2*Parametri!$B$118) -> 21.832797 | V15: =IF(B15>=Parametri!$B$99-1,Parametri!$B$98,0) -> 6 | W15: =IF(B15>=Parametri!$B$101-1,Parametri!$B$100,0) -> 5 | X15: =IF(B15>=Parametri!$B$103-1,Parametri!$B$102,0) -> 2.75 | Y15: =IF(B15>=Parametri!$B$105-1,Parametri!$B$104,0) -> 1 | Z15: =N15+O15+P15+Q15+T15+U15+V15+W15+X15+Y15 -> 29.610613 | AA15: =AA14+Z15 -> 187.03946 | AB15: =-AA15/F15 -> -0.079081569
A16: =Parametri!$B$6+B16 -> 2037 | B16: 11 | C16: =C15*(1+Parametri!$B$14) -> 23.763736 | D16: =D15*(1+Parametri!$B$15)+Parametri!$B$18*(1-Parametri!$B$15)^B15 -> 17.837684 | E16: =D16/C16 -> 0.75062624 | F16: =F15*(1+Parametri!$B$20) -> 2384.0672 | G16: =G15*(1+Parametri!$B$22) -> 26577.754 | H16: =F16*I16 -> 398.99067 | I16: =IF(B16<=(Parametri!$B$35-Parametri!$B$6),Parametri!$B$32+(Parametri!$B$33-Parametri!$B$32)*B16/(Parametri!$B$35-Parametri!$B$6),Parametri!$B$33+(Parametri!$B$34-Parametri!$B$33)*(B16-(Parametri!$B$35-Parametri!$B$6))/(2070-Parametri!$B$35)) -> 0.16735714 | J16: =H16-U16 -> 374.0213 | K16: =J16/F16 -> 0.15688371 | L16: =IF(B16<=5,Parametri!$B$55+(Parametri!$B$56-Parametri!$B$55)/5*B16,MIN(Parametri!$B$57,Parametri!$B$56+(Parametri!$B$57-Parametri!$B$56)/24*(B16-5))) -> 0.7 | M16: =L16*D16 -> 12.486379 | N16: =IF(B16<Parametri!$B$72,Parametri!$B$71*Parametri!$B$70*Parametri!$B$69/Parametri!$B$72,0) -> 0 | O16: =IF(B16<10,Parametri!$B$50,IF(B16<20,Parametri!$B$53,Parametri!$B$54))*M16*G16*Parametri!$B$68/1000 -> 5.3761304 | P16: =MIN(Parametri!$B$77+Parametri!$B$78, Parametri!$B$77+Parametri!$B$78*(B16+1)/Parametri!$B$79) -> 10.7 | Q16: =-IF(B16<10,Parametri!$B$48,IF(B16<20,Parametri!$B$51,Parametri!$B$54))*M16*G16/1000 -> -19.911594 | R16: =IF(B16<10,Parametri!$B$49,IF(B16<20,Parametri!$B$52,0))*M16*G16/1000 -> 0 | S16: 0 | T16: =-(Parametri!$B$82*(Parametri!$B$83*Parametri!$B$86+Parametri!$B$84*Parametri!$B$87+Parametri!$B$85*Parametri!$B$88)/1000000000)*MIN(B16+1,Parametri!$B$89) -> -2.93725 | U16: =Parametri!$B$45*Parametri!$B$92*13/1000000000*((B16+1)*Parametri!$B$117+B16*(B16+1)/2*Parametri!$B$118) -> 24.969368 | V16: =IF(B16>=Parametri!$B$99-1,Parametri!$B$98,0) -> 6 | W16: =IF(B16>=Parametri!$B$101-1,Parametri!$B$100,0) -> 5 | X16: =IF(B16>=Parametri!$B$103-1,Parametri!$B$102,0) -> 2.75 | Y16: =IF(B16>=Parametri!$B$105-1,Parametri!$B$104,0) -> 1 | Z16: =N16+O16+P16+Q16+T16+U16+V16+W16+X16+Y16 -> 32.946654 | AA16: =AA15+Z16 -> 219.98611 | AB16: =-AA16/F16 -> -0.092273453
A17: =Parametri!$B$6+B17 -> 2038 | B17: 12 | C17: =C16*(1+Parametri!$B$14) -> 24.001373 | D17: =D16*(1+Parametri!$B$15)+Parametri!$B$18*(1-Parametri!$B$15)^B16 -> 17.871037 | E17: =D17/C17 -> 0.74458395 | F17: =F16*(1+Parametri!$B$20) -> 2403.1397 | G17: =G16*(1+Parametri!$B$22) -> 26630.91 | H17: =F17*I17 -> 405.10069 | I17: =IF(B17<=(Parametri!$B$35-Parametri!$B$6),Parametri!$B$32+(Parametri!$B$33-Parametri!$B$32)*B17/(Parametri!$B$35-Parametri!$B$6),Parametri!$B$33+(Parametri!$B$34-Parametri!$B$33)*(B17-(Parametri!$B$35-Parametri!$B$6))/(2070-Parametri!$B$35)) -> 0.16857143 | J17: =H17-U17 -> 376.80279 | K17: =J17/F17 -> 0.15679604 | L17: =IF(B17<=5,Parametri!$B$55+(Parametri!$B$56-Parametri!$B$55)/5*B17,MIN(Parametri!$B$57,Parametri!$B$56+(Parametri!$B$57-Parametri!$B$56)/24*(B17-5))) -> 0.71666667 | M17: =L17*D17 -> 12.807577 | N17: =IF(B17<Parametri!$B$72,Parametri!$B$71*Parametri!$B$70*Parametri!$B$69/Parametri!$B$72,0) -> 0 | O17: =IF(B17<10,Parametri!$B$50,IF(B17<20,Parametri!$B$53,Parametri!$B$54))*M17*G17*Parametri!$B$68/1000 -> 5.5254542 | P17: =MIN(Parametri!$B$77+Parametri!$B$78, Parametri!$B$77+Parametri!$B$78*(B17+1)/Parametri!$B$79) -> 11.3 | Q17: =-IF(B17<10,Parametri!$B$48,IF(B17<20,Parametri!$B$51,Parametri!$B$54))*M17*G17/1000 -> -20.464645 | R17: =IF(B17<10,Parametri!$B$49,IF(B17<20,Parametri!$B$52,0))*M17*G17/1000 -> 0 | S17: 0 | T17: =-(Parametri!$B$82*(Parametri!$B$83*Parametri!$B$86+Parametri!$B$84*Parametri!$B$87+Parametri!$B$85*Parametri!$B$88)/1000000000)*MIN(B17+1,Parametri!$B$89) -> -2.93725 | U17: =Parametri!$B$45*Parametri!$B$92*13/1000000000*((B17+1)*Parametri!$B$117+B17*(B17+1)/2*Parametri!$B$118) -> 28.297901 | V17: =IF(B17>=Parametri!$B$99-1,Parametri!$B$98,0) -> 6 | W17: =IF(B17>=Parametri!$B$101-1,Parametri!$B$100,0) -> 5 | X17: =IF(B17>=Parametri!$B$103-1,Parametri!$B$102,0) -> 2.75 | Y17: =IF(B17>=Parametri!$B$105-1,Parametri!$B$104,0) -> 1 | Z17: =N17+O17+P17+Q17+T17+U17+V17+W17+X17+Y17 -> 36.47146 | AA17: =AA16+Z17 -> 256.45757 | AB17: =-AA17/F17 -> -0.10671771
... A34: =Parametri!$B$6+B34 -> 2055 | B34: 29 | C34: =C33*(1+Parametri!$B$14) -> 28.424933 | D34: =D33*(1+Parametri!$B$15)+Parametri!$B$18*(1-Parametri!$B$15)^B33 -> 18.50699 | E34: =D34/C34 -> 0.651083 | F34: =F33*(1+Parametri!$B$20) -> 2751.7442 | G34: =G33*(1+Parametri!$B$22) -> 27550.994 | H34: =F34*I34 -> 427.89623 | I34: =IF(B34<=(Parametri!$B$35-Parametri!$B$6),Parametri!$B$32+(Parametri!$B$33-Parametri!$B$32)*B34/(Parametri!$B$35-Parametri!$B$6),Parametri!$B$33+(Parametri!$B$34-Parametri!$B$33)*(B34-(Parametri!$B$35-Parametri!$B$6))/(2070-Parametri!$B$35)) -> 0.1555 | J34: =H34-U34 -> 313.6431 | K34: =J34/F34 -> 0.11397974 | L34: =IF(B34<=5,Parametri!$B$55+(Parametri!$B$56-Parametri!$B$55)/5*B34,MIN(Parametri!$B$57,Parametri!$B$56+(Parametri!$B$57-Parametri!$B$56)/24*(B34-5))) -> 1 | M34: =L34*D34 -> 18.50699 | N34: =IF(B34<Parametri!$B$72,Parametri!$B$71*Parametri!$B$70*Parametri!$B$69/Parametri!$B$72,0) -> 0 | O34: =IF(B34<10,Parametri!$B$50,IF(B34<20,Parametri!$B$53,Parametri!$B$54))*M34*G34*Parametri!$B$68/1000 -> 11.013537 | P34: =MIN(Parametri!$B$77+Parametri!$B$78, Parametri!$B$77+Parametri!$B$78*(B34+1)/Parametri!$B$79) -> 12.5 | Q34: =-IF(B34<10,Parametri!$B$48,IF(B34<20,Parametri!$B$51,Parametri!$B$54))*M34*G34/1000 -> -40.790879 | R34: =IF(B34<10,Parametri!$B$49,IF(B34<20,Parametri!$B$52,0))*M34*G34/1000 -> 0 | S34: 0 | T34: =-(Parametri!$B$82*(Parametri!$B$83*Parametri!$B$86+Parametri!$B$84*Parametri!$B$87+Parametri!$B$85*Parametri!$B$88)/1000000000)*MIN(B34+1,Parametri!$B$89) -> -2.93725 | U34: =Parametri!$B$45*Parametri!$B$92*13/1000000000*((B34+1)*Parametri!$B$117+B34*(B34+1)/2*Parametri!$B$118) -> 114.25313 | V34: =IF(B34>=Parametri!$B$99-1,Parametri!$B$98,0) -> 6 | W34: =IF(B34>=Parametri!$B$101-1,Parametri!$B$100,0) -> 5 | X34: =IF(B34>=Parametri!$B$103-1,Parametri!$B$102,0) -> 2.75 | Y34: =IF(B34>=Parametri!$B$105-1,Parametri!$B$104,0) -> 1 | Z34: =N34+O34+P34+Q34+T34+U34+V34+W34+X34+Y34 -> 108.78854 | AA34: =AA33+Z34 -> 1458.8478 | AB34: =-AA34/F34 -> -0.53015384

Sheet Output
A1: OUTPUT — INDICATORI DI SOSTENIBILITÀ (v2)
A3: 1. SPESA PENSIONISTICA SUL PIL
A4: Indicatore | B4: 2026 | C4: 2030 | D4: 2035 | E4: 2040 (picco) | F4: 2050 | G4: 2055
A5: Status quo (RGS, % PIL) | B5: =Modello!I5 -> 0.154 | C5: =Modello!I9 -> 0.15885714 | D5: =Modello!I14 -> 0.16492857 | E5: =Modello!I19 -> 0.171 | F5: =Modello!I29 -> 0.16066667 | G5: =Modello!I34 -> 0.1555
A6: Riforma (% PIL) | B6: =Modello!K5 -> 0.15353068 | C6: =Modello!K9 -> 0.15573279 | D6: =Modello!K14 -> 0.15687863 | E6: =Modello!K19 -> 0.15644857 | F6: =Modello!K29 -> 0.12919734 | G6: =Modello!K34 -> 0.11397974
A7: Risparmio (punti %) | B7: =Modello!I5-Modello!K5 -> 0.00046931786 | C7: =Modello!I9-Modello!K9 -> 0.0031243503 | D7: =Modello!I14-Modello!K14 -> 0.0080499441 | E7: =Modello!I19-Modello!K19 -> 0.014551426 | F7: =Modello!I29-Modello!K29 -> 0.031469328 | G7: =Modello!I34-Modello!K34 -> 0.041520259
A9: 2. SALDO NETTO CUMULATO DELLA RIFORMA
A10: Indicatore | B10: 2026 | C10: 2030 | D10: 2035 | E10: 2040 | F10: 2050 | G10: 2055
A11: Saldo cumulato (€mld) | B11: =Modello!AA5 -> 6.5901602 | C11: =Modello!AA9 -> 60.792842 | D11: =Modello!AA14 -> 157.42884 | E11: =Modello!AA19 -> 340.72976 | F11: =Modello!AA29 -> 972.76098 | G11: =Modello!AA34 -> 1458.8478
A12: Debito di transizione / PIL | B12: =Modello!AB5 -> -0.0030174726 | C12: =Modello!AB9 -> -0.026962346 | D12: =Modello!AB14 -> -0.067094494 | E12: =Modello!AB19 -> -0.13954362 | F12: =Modello!AB29 -> -0.36787539 | G12: =Modello!AB34 -> -0.53015384
A14: 3. INDICATORI CHIAVE
A15: Picco fabbisogno annuo (€mld, anno peggiore) | B15: =MIN(Modello!Z5:Z34) -> 6.5901602
A16: Anno del picco | B16: =INDEX(Modello!A5:A34,MATCH(MIN(Modello!Z5:Z34),Modello!Z5:Z34,0)) -> 2026
A17: BRDP totali emessi cumulati (€mld) | B17: =SUM(Modello!R5:R34) -> 49.671273
A18: BRDP esterni cumulati (€mld) | B18: =SUM(Modello!S5:S34) -> 0
A19: BRDP esterni / PIL anno 30 | B19: =SUM(Modello!S5:S34)/Modello!F34 -> 0
A20: Risparmio totale Leve G+H+I+J cumulato 30 anni | B20: =SUM(Modello!V5:Y34) -> 434.75
A22: 4. VERDETTO DI SOSTENIBILITÀ
A23: Picco fabbisogno sotto soglia 0,5% PIL? | B23: =IF(ABS(B15)/Modello!F5<=0.005,"OK","ATTENZIONE") -> OK
A24: Saldo finale (2055) positivo? | B24: =IF(G11>=0,"SI — autofinanziato","NO — fabbisogno residuo") -> SI — autofinanziato
A25: Spesa pensionistica 2055 < status quo? | B25: =IF(G6<G5,"SI — risparmio strutturale","NO — aumenta") -> SI — risparmio strutturale
A27: 5. SCENARI SENSITIVITY (da popolare manualmente)
A28: Scenario r_fondi | B28: Saldo cum. 2040 | C28: Saldo cum. 2055 | D28: Spesa rif. 2055 %PIL | E28: Debito tr./PIL 2055 | F28: Verdetto
A29: Avverso (3%) | B29: — | C29: — | D29: — | E29: — | F29: —
A30: Base (4%, attuale) | B30: — | C30: — | D30: — | E30: — | F30: —
A31: Ottimista (5%) | B31: — | C31: — | D31: — | E31: — | F31: —
A33: NOTE METODOLOGICHE
A34: • Tutti i valori in termini reali (prezzi 2026). Inflazione neutralizzata.
A35: • La traiettoria della spesa PAYG/PIL (colonna I del Modello) segue le proiezioni RGS 26/2025: 15,4 % (2026) → 17,1 % (2040) → 14 % (2070).
A36: • La Leva F è stata corretta rispetto alla v1: ora calcola il risparmio sulla SPESA PUBBLICA per i NUOVI pensionati × quota_nuovo_regime, non sullo stock totale.
A37: • La biforcazione contributiva cambia nelle 3 fasi: I (2026-2035) 2%+4%; II (2036-2045) 0%+6%; III (2046-2055) 0%+8% (framing Save More Tomorrow).
A38: • Le leve G, H, I, J sono aggiunte sulla base di Bertonelli Q18A (ricalibrazione parametrica): generano cassa immediata in attesa che le leve strutturali (D, F, C) maturino.
A39: • Il perimetro Livello 1 ora include dipendenti privati (FPLD) + dipendenti pubblici (CTPS) per un totale di 17,5 mln occupati.
A40: • Il tax gap previdenziale (10 mld/anno stima media) è inserito come dato consultivo nei Parametri ma NON è incluso nel saldo: è recupero condizionato a riforma autonomi (Livello 2).
A41: • Celle GIALLE in Parametri = ipotesi sensibili da stress-testare. Celle VERDI = parametri aggiunti rispetto alla v1.
A42: • Le celle ROSSE nella colonna Z del Modello evidenziano gli anni con saldo annuo negativo (fabbisogno).

Sheet Confronto Bertonelli
A1: CONFRONTO NUMERICO MAIN.PDF / EXCEL v2 / BERTONELLI (12 maggio 2026)
A3: Indicatore | B3: Main.pdf | C3: Excel v2 | D3: Bertonelli | E3: Verifica / Fonte ufficiale
A4: Spesa pensionistica / PIL 2024 | B4: ~16 % | C4: 15,4 % | D4: 15,4 % | E4: RGS 2024 ✓ allineato
A5: Spesa pens. % PIL — picco 2040 | B5: non citato | C5: 17,1 % al 2040 | D5: 17,1 % | E5: RGS 26/2025 ✓
A6: Spesa pens. % PIL — 2070 (rientro) | B6: non citato | C6: 14 % (lineare al 2055) | D6: 14 % | E6: RGS — ipotesi ottimistiche su produttività/migrazione
A7: Pensioni vigenti | B7: 16 mln (erroneo) | C7: 21,3 mln | D7: 21,3 mln (2026) | E7: INPS Osservatorio 1.1.2026 ✓
A8: Pensionati distinti | B8: non distinto | C8: 16,3 mln (referenza) | D8: 16,3 mln | E8: INPS Casellario ✓
A9: Cumulo pensioni/pensionato | B9: non citato | C9: 1,41 | D9: 1,41 | E9: INPS ✓
A10: Occupati (perimetro) | B10: 24 mln (totale) | C10: 17,5 mln (priv+pub L1) | D10: 23,9 mln (totale) | E10: ISTAT 2024 — perimetro Excel v2 esplicito
A11: Età pensionabile legale | B11: 67 | C11: 67 | D11: 67 | E11: L.214/2011 ✓
A12: Età pensionabile effettiva | B12: non citata | C12: 63,8 | D12: 63,8 | E12: INPS XXIV Rapp. 2025 ✓
A13: Coefficiente trasformaz. 67 anni | B13: 5,723 % | C13: 5,608 % | D13: 5,275 % (erroneo) | E13: DM MEF 20/11/2024 → 5,608 % ✓
A14: Patrimonio fondi pensione | B14: 220 mld (2023) | C14: 244 mld (2024) | D14: non citato | E14: COVIP Relazione 2024 ✓
... A25: IPD - debito pens. implicito | B25: 200-450 % PIL | C25: non parametrizzato | D25: non citato | E25: Eurostat GFS — range ampio

Sheet Fonti
A1: FONTI USATE NEL MODELLO v2
A3: # | B3: Documento / Fonte | C3: Anno | D3: Uso nel modello
A4: 1 | B4: INPS — Rendiconto generale 2024, Tab. 4.3 | C4: 2024 | D4: Spesa totale 417,4 mld / pensioni 320,6 mld; safety net 32,5 mld
A5: 2 | B5: INPS — Osservatorio Pensioni Vigenti 1.1.2026 Tav. 13 | C5: 2026 | D5: 21,3 mln pensioni; 16,3 mln pensionati; cumulo 1,41
A6: 3 | B6: INPS — XXIV Rapporto Annuale 2025 | C6: 2025 | D6: Età effettiva 63,8; tassi di sostituzione effettivi
A7: 4 | B7: INPS — Casellario Centrale Pensionati | C7: 2024 | D7: Reddito medio pensionato 1.718 €/mese
A8: 5 | B8: RGS-MEF — Rapporto 26/2025 | C8: 2025 | D8: Traiettoria spesa PAYG/PIL: 15,4% → 17,1% (2040) → 14% (2070); migrazione 165k/anno
A9: 6 | B9: RGS-MEF — Relazione evasione 2025 Tab. I.1 | C9: 2025 | D9: Tax gap contributivo 8-12 mld/anno; IRPEF autonomi 36 mld
A10: 7 | B10: DM MEF 20/11/2024 | C10: 2024 | D10: Coefficiente trasformazione 67 anni = 5,608% biennio 2025-2026
A11: 8 | B11: ISTAT — Previsioni popolazione base 1.1.2024 | C11: 2024 | D11: Trend pensionati +1%/anno; occupati -0,5%/anno
A12: 9 | B12: ISTAT — Contabilità nazionale 2024 | C12: 2024 | D12: PIL Italia 2024 = 2.184 mld €
A13: 10 | B13: Eurostat — ILC_DI03 + HICP 2005-2024 | C13: 2024 | D13: Salari reali coorti attive: NEGATIVI; corretto a g_w=+0,05%
A14: 11 | B14: Eurostat — ESSPROS spr_exp_func 2024 | C14: 2024 | D14: Iperconcentrazione vecchiaia +4,1 pp PIL vs UE (≈90 mld/anno)
A15: 12 | B15: Eurostat — demo_find | C15: 2024 | D15: Fecondità Italia 1,18 (2024)
... A33: 30 | B33: Holzmann R., Hinz R. — Old-Age Income Support | C33: 2005 WB | D33: Architettura multi-pilastro 0-1-2-3-4

Sheet Changelog
A1: CHANGELOG v1 → v2
A3: # | B3: Modifica
A5: 1 | B5: Pensione media: distinta tra 'singola prestazione' 1.218 €/mese e 'reddito pensionato' 1.718 €/mese
A6: 2 | B6: Coefficiente trasformazione 67 anni: 5,723 % → 5,608 % (DM MEF 20/11/2024)
A7: 3 | B7: Patrimonio fondi pensione: 220 mld (2023) → 244 mld (COVIP 2024)
A8: 4 | B8: PIL Italia anno 0: 2.100 → 2.184 mld (ISTAT 2024)
A9: 5 | B9: Crescita salari reali: +0,5 % → +0,05 % (Eurostat ILC_DI03 + HICP)
A10: 6 | B10: Pensioni vigenti come variabile operativa: 16 mln → 21,3 mln (con riferimento 16,3 pensionati)
A11: 7 | B11: Età pensionabile effettiva 63,8 aggiunta come parametro
A12: 8 | B12: Spesa PAYG/PIL: traiettoria RGS (15,4 % → 17,1 % al 2040 → 14 % verso 2070) invece di costanza
A13: 9 | B13: Perimetro Livello 1: dipendenti privati FPLD + dipendenti pubblici CTPS (17,5 mln)
A14: 10 | B14: Migrazione netta 165k/anno × 70 % età lavorativa = +0,116 mln occupati/anno
A15: 11 | B15: Tax gap previdenziale 10 mld/anno aggiunto (consultivo, non nel saldo riforma)
A18: 12 | B18: Leva F (P0 sostitutivo) RIFORMULATA: risparmio = NUOVI pensionati × quota_nuovo_regime × (PensMedia − P0). Non più sullo stock totale.
... A40: 28 | B40: Foglio 'Changelog': questo elenco
