Workbook

Sheet Parametri
A1: MODELLO QUANTITATIVO DELLA PROPOSTA DI RIFORMA PENSIONISTICA
A2: Foglio dei parametri — celle gialle = ipotesi chiave; celle verdi = parametri aggiunti rispetto a v1
A4: Parametro | B4: Valore | C4: Unità | D4: Note metodologiche | E4: Fonte
A5: DEMOGRAFIA E MACRO
A6: Anno iniziale | B6: 2027 | C6: anno | D6: Anno di partenza simulazione | E6: RGS 26/2025
A7: Orizzonte temporale | B7: 34 | C7: anni | D7: 2027-2060: copertura completa fino al picco demografico e discesa | E7: RGS 26/2025 — orizzonte a 2060
A8: Pensionati distinti (anno 0) | B8: 17 | C8: mln | D8: Pensionati fisici al 31/12/2026 ≈ 17.0 mln — crescita ~0.5 mln/anno da 16.3 (INPS flussi) | E8: INPS Osservatorio 2024 + stima flusso 2025-2026
A9: Pensioni vigenti (anno 0) | B9: 22.3 | C9: mln | D9: Pensioni vigenti al 1.1.2027 ≈ 22.3 mln (+1 mln da 21.3 nel 2024, flusso netto ~500k/anno) | E9: INPS Osservatorio Pensioni Vigenti 2024 + stima flusso
A10: Cumulo medio pensioni/pensionato | B10: =B9/B8 -> 1.3117647 | C10: n | D10: 21,3/16,3 = 1,31 — strutturale (vecchiaia+reversibilità) | E10: INPS Casellario 31/12/2024
A11: Occupati dipendenti privati (FPLD) | B11: 14 | C11: mln | D11: Perimetro Livello 1 base | E11: INPS-FPLD 2024
A12: Occupati dipendenti pubblici (CTPS) | B12: 3.5 | C12: mln | D12: Pubblici impiegati gestione separata CTPS | E12: INPS CTPS 2024
A13: Totale occupati Livello 1 | B13: 17.5 | C13: mln | D13: Dipendenti privati + pubblici — perimetro modello base | E13: Somma
A14: Crescita reale pensioni vigenti | B14: 0.006 | C14: %/anno | D14: AGGIORNATO +0.6%/anno: baby boom 2027-2036 acc. ingresso (AR2024: dep.ratio +7.2pp in 2022-2040) | E14: AR2024 Table 2 + RGS 26/2025 demografia
A15: Crescita reale occupati (al netto migrazione) | B15: -0.005 | C15: %/anno | D15: Trend demografico ISTAT base 2024 | E15: ISTAT
A16: Migrazione netta annua (scenario RGS) | B16: 176000 | C16: persone/anno | D16: AGGIORNATO: RGS 26/2025 usa 176k netti/anno scenario base (AR2024 Eurostat: 270k ottimistico) | E16: RGS 26/2025 scenario base migrazione
A17: Quota migranti in età lavorativa | B17: 0.7 | C17: % | D17: Stima Moressa: ~70% migranti sono 25-54 | E17: Moressa XV Rapporto 2025
A18: Effetto netto su occupati (mln/anno) | B18: 0.116 | C18: mln/anno | D18: 165k × 70% = 115,5k nuovi occupati lordi annui | E18: Derivato
A19: PIL reale anno 0 | B19: 2237 | C19: €mld | D19: PIL reale 2027 (€mld): 2184*(1.006)*(1.007)*(1.008)≈2237 — DEF 2025 g=0.8% in 2027 | E19: ISTAT contabilità nazionale 2024 + DEF 2025
A20: Crescita reale PIL (g) | B20: 0.008 | C20: %/anno | D20: CONFERMATA: DEF 2025 +0.8% nel 2027; AR2024 usa 0.8% trend produttività strutturale | E20: DEF 2025 + Ageing Report 2024 macro assumptions
A21: Salario imponibile medio | B21: 26700 | C21: €/anno | D21: AGGIORNATO: salario imponibile medio 2027 ≈ 26.700€ (26.000 nel 2024 + 3 anni × +0.2% reale) | E21: INPS FPLD 2024 + Eurostat ILC_DI03 growth trend
A22: Crescita reale salari (g_w) | B22: 0.002 | C22: %/anno | D22: CORRETTO dal +0,5% v1 a +0,05%: Eurostat ILC_DI03 mostra reale NEGATIVO per coorti attive 2005-2024 | E22: Eurostat ILC_DI03 + HICP 2005-2024
A24: SISTEMA ATTUALE (PAYG)
A25: Aliquota contributiva (dipendenti) | B25: 0.33 | C25: % | D25: 9,19% lavoratore + 23,81% datore | E25: INPS aliquote 2024
A26: Pensione media mensile (singola prestazione) | B26: 1218 | C26: €/mese | D26: AGGIORNATO: importo medio della SINGOLA prestazione (era 1.350 = pens. di vecchiaia) | E26: INPS Osservatorio 2024 — Q5 Bertonelli
A27: Reddito medio del pensionato | B27: 1718 | C27: €/mese | D27: 22.331 €/anno / 13 — somma 1,41 pensioni cumulate | E27: INPS Casellario 2024
A28: Mensilità annue | B28: 13 | C28: n | D28: Standard previdenziale italiano | E28: Norma
A29: Età pensionabile legale | B29: 67 | C29: anni | D29: Vecchiaia 2026 (Riforma Fornero) | E29: L. 214/2011
A30: Età pensionabile effettiva | B30: 64.8 | C30: anni | D30: AGGIUNTA: età effettiva media INPS 2024 (privati+autonomi) | E30: INPS XXIV Rapporto 2025
A31: Coefficiente trasformazione a 67 anni | B31: 0.05608 | C31: % | D31: AGGIORNATO 5,723%→5,608% biennio 2025-2026 | E31: DM MEF 20/11/2024
A32: Spesa PAYG/PIL anno 0 (status quo) | B32: 0.16 | C32: % | D32: AGGIORNATO 16.0% al 2027: interp. AR2024 15.4%(2024)→16.6%(2030), RGS conferma 15.4% 2024 | E32: AR2024 Table 6 + RGS 26/2025
A33: Spesa PAYG/PIL picco 2040 | B33: 0.171 | C33: % | D33: Picco 17.1% al 2040 CONFERMATO da RGS 26/2025; AR2024 mostra 17.3% al 2036 con schema diverso | E33: RGS 26/2025 + AR2024 Table 6
A34: Spesa PAYG/PIL fine orizzonte (2060) | B34: 0.141 | C34: % | D34: AGGIORNATO 14.1% al 2060: RGS 26/2025 esplicito (sostituisce 14.0% al 2070 della v3) | E34: RGS 26/2025 pag.14 esplicito
A35: Anno picco spesa/PIL | B35: 2040 | C35: anno | D35: Anno picco CONFERMATO 2040 per RGS 26/2025 (AR2024: 2036, schema leggermente diverso) | E35: RGS 26/2025
A36: Anno fine orizzonte | B36: 2060 | C36: anno | D36: Fine previsione: 2060 — raccordo con RGS 26/2025 (14.1% PIL) e AR2024 (13.7% PIL) | E36: RGS 26/2025 + AR2024
A38: PILASTRO 0 — SUSSIDIO UNIVERSALE
A39: P0 base mensile (B) | B39: 650 | C39: €/mese | D39: Sopra soglia povertà ISTAT (€598 Nord) | E39: Calibrazione propria
A40: Aliquota di taper (t) | B40: =B39/B41 -> 0.52 | C40: % | D40: EMRT 52% nella zona di taper | E40: Ingles-Stewart 2017 (Australia)
A41: Cap reddito totale | B41: 1250 | C41: €/mese | D41: P0=0 oltre B/t = 1.250 | E41: B/t
A42: Franchigia patrimoniale | B42: 50000 | C42: € | D42: Patrimonio escluso dal deemed rate | E42: Modello AU/UK
A43: Deemed rate | B43: 0.045 | C43: % | D43: Rendimento figurativo (era 7,8% AU post-2017, ridotto) | E43: Cilibrato vs AU
...

Sheet Modello
A1: MODELLO — PROIEZIONE ANNO PER ANNO (v2, 34 anni 2027-2060)
A2: Tutti i valori in termini reali (prezzi 2027). Flussi positivi = risparmi/entrate per lo Stato; negativi = costi/fabbisogno.
W3: Stock BRDP vivo — formula aggregata (interno+esterno) =SUM(Z)+SUM(AA). Rimborso AD include sia Z(t-15) sia AA(t-15) — v9.
A4: Anno | B4: t | C4: Pensioni vigenti (mln) | D4: Occupati L1 (mln) | E4: Att/Pens | F4: PIL reale (€mld) | G4: Salario medio (€) | H4: Spesa PAYG SQ (€mld) | I4: Spesa PAYG %PIL (RGS) | J4: Spesa rif. (€mld) | K4: Spesa rif./PIL | L4: %Lav in P2 | M4: Lav. in P2 (mln) | N4: Leva A (€mld) | O4: Leva B (€mld) | P4: Leva C (€mld) | Q4: Leva D gap (€mld) | R4: Leva D ai fondi | S4: Leva D fondi cum | T4: Leva E (€mld) | U4: Leva F CORRETTA | V4: Leva G (€mld) | W4: Leva H (€mld) | X4: Leva I (€mld) | Y4: Leva J (€mld) | Z4: BRDP emessi (€mld) | AA4: BRDP esterni (€mld) | AB4: Stock BRDP totale (€mld) | AC4: Interessi BRDP (€mld) | AD4: Rimborso cap. BRDP (€mld) | AE4: Saldo annuo (€mld) | AF4: Saldo cum. (€mld) | AG4: Debito tr./PIL | AH4: Stock BRDP interno (€mld) | AI4: Rimborso cap. BRDP interno (€mld)
A5: =Parametri!$B$6+B5 -> 2027 | B5: 0 | C5: =Parametri!$B$9 -> 22.3 | D5: =CHOOSE(Parametri!$B$143,Parametri!$B$13,Parametri!$B$13+Parametri!$B$146,Parametri!$B$13+Parametri!$B$146) -> 17.5 | E5: =D5/C5 -> 0.78475336 | F5: =Parametri!$B$19 -> 2237 | G5: =CHOOSE(Parametri!$B$143,Parametri!$B$21,Parametri!$B$155,Parametri!$B$155) -> 26700 | H5: =F5*I5 -> 357.92 | I5: =IF(B5<=(Parametri!$B$35-Parametri!$B$6),Parametri!$B$32+(Parametri!$B$33-Parametri!$B$32)*B5/(Parametri!$B$35-Parametri!$B$6),Parametri!$B$33+(Parametri!$B$34-Parametri!$B$33)*(B5-(Parametri!$B$35-Parametri!$B$6))/(Parametri!$B$36-Parametri!$B$35)) -> 0.16 | J5: =H5-AE5 -> 348.56105 | K5: =J5/F5 -> 0.1558163 | L5: =IF(B5<=5,Parametri!$B$58+(Parametri!$B$59-Parametri!$B$58)/5*B5,MIN(Parametri!$B$60,Parametri!$B$59+(Parametri!$B$60-Parametri!$B$59)/24*(B5-5))) -> 0.33 | M5: =L5*D5 -> 5.775 | N5: =IF(B5<Parametri!$B$76,Parametri!$B$75*Parametri!$B$74*Parametri!$B$73/Parametri!$B$76,0) -> 2.44 | O5: =IF(B5<10,Parametri!$B$53,IF(B5<20,Parametri!$B$56,Parametri!$B$57))*M5*G5*Parametri!$B$72/1000 -> 1.665279 | P5: =MIN(Parametri!$B$81+Parametri!$B$82, Parametri!$B$81+Parametri!$B$82*(B5+1)/Parametri!$B$83) -> 4.1 | Q5: =-IF(B5<10,Parametri!$B$51,IF(B5<20,Parametri!$B$54,Parametri!$B$57))*M5*G5/1000 -> -9.25155 | R5: =-Q5-Z5 -> 6.1677 | S5: =R5 -> 6.1677 | T5: =-(Parametri!$B$86*(Parametri!$B$87*Parametri!$B$90+Parametri!$B$88*Parametri!$B$91+Parametri!$B$89*Parametri!$B$92)/1000000000)*MIN(B5+1,Parametri!$B$93) -> -0.57195 | U5: =IF(B5<Parametri!$B$125,Parametri!$B$46,IF(B5<Parametri!$B$126,Parametri!$B$47,Parametri!$B$48))*Parametri!$B$96*13/1000000000*((B5+1)*Parametri!$B$121+B5*(B5+1)/2*Parametri!$B$122) -> 0.93957435 | V5: =IF(B5>=Parametri!$B$103-1,Parametri!$B$102*(1-Parametri!$B$127)^(B5-(Parametri!$B$103-1)),0) -> 6 | W5: =IF(B5>=Parametri!$B$105-1,Parametri!$B$104,0) -> 0 | X5: =IF(B5>=Parametri!$B$107-1,Parametri!$B$106+Parametri!$B$128*INT((B5-(Parametri!$B$107-1))/2),0) -> 0 | Y5: =IF(AND(B5>=Parametri!$B$109-1,B5<Parametri!$B$109-1+Parametri!$B$140),Parametri!$B$108,0) -> 1 | Z5: =IF(B5<10,Parametri!$B$52,IF(B5<20,Parametri!$B$55,0))*M5*G5/1000 -> 3.08385 | AA5: =Parametri!$B$159*Parametri!$B$160 -> 0 | AB5: =SUM(Z$5:Z5)+SUM(AA$5:AA5) -> 3.08385 | AC5: =-(Parametri!$B$67*SUM(Z$5:Z5)+Parametri!$B$161*SUM(AA$5:AA5)) -> -0.04625775 | AD5: =0 -> 0 | AE5: =Z5+AA5+N5+O5+P5+Q5+T5+U5+V5+W5+X5+Y5+AC5+AD5 -> 9.3589456 | AF5: =AE5 -> 9.3589456 | AG5: =-AF5/F5 -> -0.0041837039 | AH5: =SUM(Z$5:Z5) -> 3.08385 | AI5: 0
A6: =Parametri!$B$6+B6 -> 2028 | B6: 1 | C6: =C5*(1+Parametri!$B$14) -> 22.4338 | D6: =D5*(1+Parametri!$B$15)+Parametri!$B$145*(1-Parametri!$B$15)^B5 -> 17.5285 | E6: =D6/C6 -> 0.78134333 | F6: =F5*(1+Parametri!$B$20) -> 2254.896 | G6: =G5*(1+Parametri!$B$22) -> 26753.4 | H6: =F6*I6 -> 362.69135 | I6: =IF(B6<=(Parametri!$B$35-Parametri!$B$6),Parametri!$B$32+(Parametri!$B$33-Parametri!$B$32)*B6/(Parametri!$B$35-Parametri!$B$6),Parametri!$B$33+(Parametri!$B$34-Parametri!$B$33)*(B6-(Parametri!$B$35-Parametri!$B$6))/(Parametri!$B$36-Parametri!$B$35)) -> 0.16084615 | J6: =H6-AE6 -> 345.33862 | K6: =J6/F6 -> 0.15315058 | L6: =IF(B6<=5,Parametri!$B$58+(Parametri!$B$59-Parametri!$B$58)/5*B6,MIN(Parametri!$B$60,Parametri!$B$59+(Parametri!$B$60-Parametri!$B$59)/24*(B6-5))) -> 0.384 | M6: =L6*D6 -> 6.730944 | N6: =IF(B6<Parametri!$B$76,Parametri!$B$75*Parametri!$B$74*Parametri!$B$73/Parametri!$B$76,0) -> 2.44 | O6: =IF(B6<10,Parametri!$B$53,IF(B6<20,Parametri!$B$56,Parametri!$B$57))*M6*G6*Parametri!$B$72/1000 -> 1.9448169 | P6: =MIN(Parametri!$B$81+Parametri!$B$82, Parametri!$B$81+Parametri!$B$82*(B6+1)/Parametri!$B$83) -> 4.7 | Q6: =-IF(B6<10,Parametri!$B$51,IF(B6<20,Parametri!$B$54,Parametri!$B$57))*M6*G6/1000 -> -10.804538 | R6: =-Q6-Z6 -> 7.2030255 | S6: =S5+R6 -> 13.370725 | T6: =-(Parametri!$B$86*(Parametri!$B$87*Parametri!$B$90+Parametri!$B$88*Parametri!$B$91+Parametri!$B$89*Parametri!$B$92)/1000000000)*MIN(B6+1,Parametri!$B$93) -> -1.1439 | U6: =IF(B6<Parametri!$B$125,Parametri!$B$46,IF(B6<Parametri!$B$126,Parametri!$B$47,Parametri!$B$48))*Parametri!$B$96*13/1000000000*((B6+1)*Parametri!$B$121+B6*(B6+1)/2*Parametri!$B$122) -> 2.0551138 | V6: =IF(B6>=Parametri!$B$103-1,Parametri!$B$102*(1-Parametri!$B$127)^(B6-(Parametri!$B$103-1)),0) -> 5.91 | W6: =IF(B6>=Parametri!$B$105-1,Parametri!$B$104,0) -> 5 | X6: =IF(B6>=Parametri!$B$107-1,Parametri!$B$106+Parametri!$B$128*INT((B6-(Parametri!$B$107-1))/2),0) -> 2.75 | Y6: =IF(AND(B6>=Parametri!$B$109-1,B6<Parametri!$B$109-1+Parametri!$B$140),Parametri!$B$108,0) -> 1 | Z6: =IF(B6<10,Parametri!$B$52,IF(B6<20,Parametri!$B$55,0))*M6*G6/1000 -> 3.6015127 | AA6: =Parametri!$B$159*Parametri!$B$160 -> 0 | AB6: =SUM(Z$5:Z6)+SUM(AA$5:AA6) -> 6.6853627 | AC6: =-(Parametri!$B$67*SUM(Z$5:Z6)+Parametri!$B$161*SUM(AA$5:AA6)) -> -0.10028044 | AD6: =0 -> 0 | AE6: =Z6+AA6+N6+O6+P6+Q6+T6+U6+V6+W6+X6+Y6+AC6+AD6 -> 17.352725 | AF6: =AF5+AE6 -> 26.71167 | AG6: =-AF6/F6 -> -0.011846076 | AH6: =SUM(Z$5:Z6) -> 6.6853627 | AI6: 0
A7: =Parametri!$B$6+B7 -> 2029 | B7: 2 | C7: =C6*(1+Parametri!$B$14) -> 22.568403 | D7: =D6*(1+Parametri!$B$15)+Parametri!$B$145*(1-Parametri!$B$15)^B6 -> 17.557437 | E7: =D7/C7 -> 0.77796544 | F7: =F6*(1+Parametri!$B$20) -> 2272.9352 | G7: =G6*(1+Parametri!$B$22) -> 26806.907 | H7: =F7*I7 -> 367.51613 | I7: =IF(B7<=(Parametri!$B$35-Parametri!$B$6),Parametri!$B$32+(Parametri!$B$33-Parametri!$B$32)*B7/(Parametri!$B$35-Parametri!$B$6),Parametri!$B$33+(Parametri!$B$34-Parametri!$B$33)*(B7-(Parametri!$B$35-Parametri!$B$6))/(Parametri!$B$36-Parametri!$B$35)) -> 0.16169231 | J7: =H7-AE7 -> 349.7557 | K7: =J7/F7 -> 0.15387843 | L7: =IF(B7<=5,Parametri!$B$58+(Parametri!$B$59-Parametri!$B$58)/5*B7,MIN(Parametri!$B$60,Parametri!$B$59+(Parametri!$B$60-Parametri!$B$59)/24*(B7-5))) -> 0.438 | M7: =L7*D7 -> 7.6901576 | N7: =IF(B7<Parametri!$B$76,Parametri!$B$75*Parametri!$B$74*Parametri!$B$73/Parametri!$B$76,0) -> 2.44 | O7: =IF(B7<10,Parametri!$B$53,IF(B7<20,Parametri!$B$56,Parametri!$B$57))*M7*G7*Parametri!$B$72/1000 -> 2.2264129 | P7: =MIN(Parametri!$B$81+Parametri!$B$82, Parametri!$B$81+Parametri!$B$82*(B7+1)/Parametri!$B$83) -> 5.3 | Q7: =-IF(B7<10,Parametri!$B$51,IF(B7<20,Parametri!$B$54,Parametri!$B$57))*M7*G7/1000 -> -12.36896 | R7: =-Q7-Z7 -> 8.2459735 | S7: =S6+R7 -> 21.616699 | T7: =-(Parametri!$B$86*(Parametri!$B$87*Parametri!$B$90+Parametri!$B$88*Parametri!$B$91+Parametri!$B$89*Parametri!$B$92)/1000000000)*MIN(B7+1,Parametri!$B$93) -> -1.71585 | U7: =IF(B7<Parametri!$B$125,Parametri!$B$46,IF(B7<Parametri!$B$126,Parametri!$B$47,Parametri!$B$48))*Parametri!$B$96*13/1000000000*((B7+1)*Parametri!$B$121+B7*(B7+1)/2*Parametri!$B$122) -> 3.3466183 | V7: =IF(B7>=Parametri!$B$103-1,Parametri!$B$102*(1-Parametri!$B$127)^(B7-(Parametri!$B$103-1)),0) -> 5.82135 | W7: =IF(B7>=Parametri!$B$105-1,Parametri!$B$104,0) -> 5 | X7: =IF(B7>=Parametri!$B$107-1,Parametri!$B$106+Parametri!$B$128*INT((B7-(Parametri!$B$107-1))/2),0) -> 2.75 | Y7: =IF(AND(B7>=Parametri!$B$109-1,B7<Parametri!$B$109-1+Parametri!$B$140),Parametri!$B$108,0) -> 1 | Z7: =IF(B7<10,Parametri!$B$52,IF(B7<20,Parametri!$B$55,0))*M7*G7/1000 -> 4.1229868 | AA7: =Parametri!$B$159*Parametri!$B$160 -> 0 | AB7: =SUM(Z$5:Z7)+SUM(AA$5:AA7) -> 10.80835 | AC7: =-(Parametri!$B$67*SUM(Z$5:Z7)+Parametri!$B$161*SUM(AA$5:AA7)) -> -0.16212524 | AD7: =0 -> 0 | AE7: =Z7+AA7+N7+O7+P7+Q7+T7+U7+V7+W7+X7+Y7+AC7+AD7 -> 17.760432 | AF7: =AF6+AE7 -> 44.472103 | AG7: =-AF7/F7 -> -0.019565935 | AH7: =SUM(Z$5:Z7) -> 10.80835 | AI7: 0
A8: =Parametri!$B$6+B8 -> 2030 | B8: 3 | C8: =C7*(1+Parametri!$B$14) -> 22.703813 | D8: =D7*(1+Parametri!$B$15)+Parametri!$B$145*(1-Parametri!$B$15)^B7 -> 17.586813 | E8: =D8/C8 -> 0.77461936 | F8: =F7*(1+Parametri!$B$20) -> 2291.1186 | G8: =G7*(1+Parametri!$B$22) -> 26860.521 | H8: =F8*I8 -> 372.3949 | I8: =IF(B8<=(Parametri!$B$35-Parametri!$B$6),Parametri!$B$32+(Parametri!$B$33-Parametri!$B$32)*B8/(Parametri!$B$35-Parametri!$B$6),Parametri!$B$33+(Parametri!$B$34-Parametri!$B$33)*(B8-(Parametri!$B$35-Parametri!$B$6))/(Parametri!$B$36-Parametri!$B$35)) -> 0.16253846 | J8: =H8-AE8 -> 357.36299 | K8: =J8/F8 -> 0.15597751 | L8: =IF(B8<=5,Parametri!$B$58+(Parametri!$B$59-Parametri!$B$58)/5*B8,MIN(Parametri!$B$60,Parametri!$B$59+(Parametri!$B$60-Parametri!$B$59)/24*(B8-5))) -> 0.492 | M8: =L8*D8 -> 8.6527121 | N8: =IF(B8<Parametri!$B$76,Parametri!$B$75*Parametri!$B$74*Parametri!$B$73/Parametri!$B$76,0) -> 0 | O8: =IF(B8<10,Parametri!$B$53,IF(B8<20,Parametri!$B$56,Parametri!$B$57))*M8*G8*Parametri!$B$72/1000 -> 2.5100966 | P8: =MIN(Parametri!$B$81+Parametri!$B$82, Parametri!$B$81+Parametri!$B$82*(B8+1)/Parametri!$B$83) -> 5.9 | Q8: =-IF(B8<10,Parametri!$B$51,IF(B8<20,Parametri!$B$54,Parametri!$B$57))*M8*G8/1000 -> -13.944981 | R8: =-Q8-Z8 -> 9.2966541 | S8: =S7+R8 -> 30.913353 | T8: =-(Parametri!$B$86*(Parametri!$B$87*Parametri!$B$90+Parametri!$B$88*Parametri!$B$91+Parametri!$B$89*Parametri!$B$92)/1000000000)*MIN(B8+1,Parametri!$B$93) -> -2.2878 | U8: =IF(B8<Parametri!$B$125,Parametri!$B$46,IF(B8<Parametri!$B$126,Parametri!$B$47,Parametri!$B$48))*Parametri!$B$96*13/1000000000*((B8+1)*Parametri!$B$121+B8*(B8+1)/2*Parametri!$B$122) -> 4.8140878 | V8: =IF(B8>=Parametri!$B$103-1,Parametri!$B$102*(1-Parametri!$B$127)^(B8-(Parametri!$B$103-1)),0) -> 5.7340298 | W8: =IF(B8>=Parametri!$B$105-1,Parametri!$B$104,0) -> 5 | X8: =IF(B8>=Parametri!$B$107-1,Parametri!$B$106+Parametri!$B$128*INT((B8-(Parametri!$B$107-1))/2),0) -> 2.89 | Y8: =IF(AND(B8>=Parametri!$B$109-1,B8<Parametri!$B$109-1+Parametri!$B$140),Parametri!$B$108,0) -> 0 | Z8: =IF(B8<10,Parametri!$B$52,IF(B8<20,Parametri!$B$55,0))*M8*G8/1000 -> 4.648327 | AA8: =Parametri!$B$159*Parametri!$B$160 -> 0 | AB8: =SUM(Z$5:Z8)+SUM(AA$5:AA8) -> 15.456677 | AC8: =-(Parametri!$B$67*SUM(Z$5:Z8)+Parametri!$B$161*SUM(AA$5:AA8)) -> -0.23185015 | AD8: =0 -> 0 | AE8: =Z8+AA8+N8+O8+P8+Q8+T8+U8+V8+W8+X8+Y8+AC8+AD8 -> 15.03191 | AF8: =AF7+AE8 -> 59.504013 | AG8: =-AF8/F8 -> -0.025971598 | AH8: =SUM(Z$5:Z8) -> 15.456677 | AI8: 0
A9: =Parametri!$B$6+B9 -> 2031 | B9: 4 | C9: =C8*(1+Parametri!$B$14) -> 22.840036 | D9: =D8*(1+Parametri!$B$15)+Parametri!$B$145*(1-Parametri!$B$15)^B8 -> 17.616628 | E9: =D9/C9 -> 0.77130473 | F9: =F8*(1+Parametri!$B$20) -> 2309.4476 | G9: =G8*(1+Parametri!$B$22) -> 26914.242 | H9: =F9*I9 -> 377.32821 | I9: =IF(B9<=(Parametri!$B$35-Parametri!$B$6),Parametri!$B$32+(Parametri!$B$33-Parametri!$B$32)*B9/(Parametri!$B$35-Parametri!$B$6),Parametri!$B$33+(Parametri!$B$34-Parametri!$B$33)*(B9-(Parametri!$B$35-Parametri!$B$6))/(Parametri!$B$36-Parametri!$B$35)) -> 0.16338462 | J9: =H9-AE9 -> 360.97416 | K9: =J9/F9 -> 0.15630325 | L9: =IF(B9<=5,Parametri!$B$58+(Parametri!$B$59-Parametri!$B$58)/5*B9,MIN(Parametri!$B$60,Parametri!$B$59+(Parametri!$B$60-Parametri!$B$59)/24*(B9-5))) -> 0.546 | M9: =L9*D9 -> 9.6186788 | N9: =IF(B9<Parametri!$B$76,Parametri!$B$75*Parametri!$B$74*Parametri!$B$73/Parametri!$B$76,0) -> 0 | O9: =IF(B9<10,Parametri!$B$53,IF(B9<20,Parametri!$B$56,Parametri!$B$57))*M9*G9*Parametri!$B$72/1000 -> 2.795898 | P9: =MIN(Parametri!$B$81+Parametri!$B$82, Parametri!$B$81+Parametri!$B$82*(B9+1)/Parametri!$B$83) -> 6.5 | Q9: =-IF(B9<10,Parametri!$B$51,IF(B9<20,Parametri!$B$54,Parametri!$B$57))*M9*G9/1000 -> -15.532767 | R9: =-Q9-Z9 -> 10.355178 | S9: =S8+R9 -> 41.268531 | T9: =-(Parametri!$B$86*(Parametri!$B$87*Parametri!$B$90+Parametri!$B$88*Parametri!$B$91+Parametri!$B$89*Parametri!$B$92)/1000000000)*MIN(B9+1,Parametri!$B$93) -> -2.85975 | U9: =IF(B9<Parametri!$B$125,Parametri!$B$46,IF(B9<Parametri!$B$126,Parametri!$B$47,Parametri!$B$48))*Parametri!$B$96*13/1000000000*((B9+1)*Parametri!$B$121+B9*(B9+1)/2*Parametri!$B$122) -> 7.04457 | V9: =IF(B9>=Parametri!$B$103-1,Parametri!$B$102*(1-Parametri!$B$127)^(B9-(Parametri!$B$103-1)),0) -> 5.6480193 | W9: =IF(B9>=Parametri!$B$105-1,Parametri!$B$104,0) -> 5 | X9: =IF(B9>=Parametri!$B$107-1,Parametri!$B$106+Parametri!$B$128*INT((B9-(Parametri!$B$107-1))/2),0) -> 2.89 | Y9: =IF(AND(B9>=Parametri!$B$109-1,B9<Parametri!$B$109-1+Parametri!$B$140),Parametri!$B$108,0) -> 0 | Z9: =IF(B9<10,Parametri!$B$52,IF(B9<20,Parametri!$B$55,0))*M9*G9/1000 -> 5.1775889 | AA9: =Parametri!$B$159*Parametri!$B$160 -> 0 | AB9: =SUM(Z$5:Z9)+SUM(AA$5:AA9) -> 20.634265 | AC9: =-(Parametri!$B$67*SUM(Z$5:Z9)+Parametri!$B$161*SUM(AA$5:AA9)) -> -0.30951398 | AD9: =0 -> 0 | AE9: =Z9+AA9+N9+O9+P9+Q9+T9+U9+V9+W9+X9+Y9+AC9+AD9 -> 16.354045 | AF9: =AF8+AE9 -> 75.858058 | AG9: =-AF9/F9 -> -0.032846841 | AH9: =SUM(Z$5:Z9) -> 20.634265 | AI9: 0
A10: =Parametri!$B$6+B10 -> 2032 | B10: 5 | C10: =C9*(1+Parametri!$B$14) -> 22.977076 | D10: =D9*(1+Parametri!$B$15)+Parametri!$B$145*(1-Parametri!$B$15)^B9 -> 17.646882 | E10: =D10/C10 -> 0.76802122 | F10: =F9*(1+Parametri!$B$20) -> 2327.9232 | G10: =G9*(1+Parametri!$B$22) -> 26968.07 | H10: =F10*I10 -> 382.31661 | I10: =IF(B10<=(Parametri!$B$35-Parametri!$B$6),Parametri!$B$32+(Parametri!$B$33-Parametri!$B$32)*B10/(Parametri!$B$35-Parametri!$B$6),Parametri!$B$33+(Parametri!$B$34-Parametri!$B$33)*(B10-(Parametri!$B$35-Parametri!$B$6))/(Parametri!$B$36-Parametri!$B$35)) -> 0.16423077 | J10: =H10-AE10 -> 364.18668 | K10: =J10/F10 -> 0.15644274 | L10: =IF(B10<=5,Parametri!$B$58+(Parametri!$B$59-Parametri!$B$58)/5*B10,MIN(Parametri!$B$60,Parametri!$B$59+(Parametri!$B$60-Parametri!$B$59)/24*(B10-5))) -> 0.6 | M10: =L10*D10 -> 10.588129 | N10: =IF(B10<Parametri!$B$76,Parametri!$B$75*Parametri!$B$74*Parametri!$B$73/Parametri!$B$76,0) -> 0 | O10: =IF(B10<10,Parametri!$B$53,IF(B10<20,Parametri!$B$56,Parametri!$B$57))*M10*G10*Parametri!$B$72/1000 -> 3.0838473 | P10: =MIN(Parametri!$B$81+Parametri!$B$82, Parametri!$B$81+Parametri!$B$82*(B10+1)/Parametri!$B$83) -> 7.1 | Q10: =-IF(B10<10,Parametri!$B$51,IF(B10<20,Parametri!$B$54,Parametri!$B$57))*M10*G10/1000 -> -17.132485 | R10: =-Q10-Z10 -> 11.421657 | S10: =S9+R10 -> 52.690187 | T10: =-(Parametri!$B$86*(Parametri!$B$87*Parametri!$B$90+Parametri!$B$88*Parametri!$B$91+Parametri!$B$89*Parametri!$B$92)/1000000000)*MIN(B10+1,Parametri!$B$93) -> -2.85975 | U10: =IF(B10<Parametri!$B$125,Parametri!$B$46,IF(B10<Parametri!$B$126,Parametri!$B$47,Parametri!$B$48))*Parametri!$B$96*13/1000000000*((B10+1)*Parametri!$B$121+B10*(B10+1)/2*Parametri!$B$122) -> 9.0293697 | V10: =IF(B10>=Parametri!$B$103-1,Parametri!$B$102*(1-Parametri!$B$127)^(B10-(Parametri!$B$103-1)),0) -> 5.563299 | W10: =IF(B10>=Parametri!$B$105-1,Parametri!$B$104,0) -> 5 | X10: =IF(B10>=Parametri!$B$107-1,Parametri!$B$106+Parametri!$B$128*INT((B10-(Parametri!$B$107-1))/2),0) -> 3.03 | Y10: =IF(AND(B10>=Parametri!$B$109-1,B10<Parametri!$B$109-1+Parametri!$B$140),Parametri!$B$108,0) -> 0 | Z10: =IF(B10<10,Parametri!$B$52,IF(B10<20,Parametri!$B$55,0))*M10*G10/1000 -> 5.7108283 | AA10: =Parametri!$B$159*Parametri!$B$160 -> 0 | AB10: =SUM(Z$5:Z10)+SUM(AA$5:AA10) -> 26.345094 | AC10: =-(Parametri!$B$67*SUM(Z$5:Z10)+Parametri!$B$161*SUM(AA$5:AA10)) -> -0.39517641 | AD10: =0 -> 0 | AE10: =Z10+AA10+N10+O10+P10+Q10+T10+U10+V10+W10+X10+Y10+AC10+AD10 -> 18.129933 | AF10: =AF9+AE10 -> 93.987991 | AG10: =-AF10/F10 -> -0.040374181 | AH10: =SUM(Z$5:Z10) -> 26.345094 | AI10: 0
A11: =Parametri!$B$6+B11 -> 2033 | B11: 6 | C11: =C10*(1+Parametri!$B$14) -> 23.114939 | D11: =D10*(1+Parametri!$B$15)+Parametri!$B$145*(1-Parametri!$B$15)^B10 -> 17.677577 | E11: =D11/C11 -> 0.76476849 | F11: =F10*(1+Parametri!$B$20) -> 2346.5466 | G11: =G10*(1+Parametri!$B$22) -> 27022.006 | H11: =F11*I11 -> 387.36069 | I11: =IF(B11<=(Parametri!$B$35-Parametri!$B$6),Parametri!$B$32+(Parametri!$B$33-Parametri!$B$32)*B11/(Parametri!$B$35-Parametri!$B$6),Parametri!$B$33+(Parametri!$B$34-Parametri!$B$33)*(B11-(Parametri!$B$35-Parametri!$B$6))/(Parametri!$B$36-Parametri!$B$35)) -> 0.16507692 | J11: =H11-AE11 -> 366.88949 | K11: =J11/F11 -> 0.15635296 | L11: =IF(B11<=5,Parametri!$B$58+(Parametri!$B$59-Parametri!$B$58)/5*B11,MIN(Parametri!$B$60,Parametri!$B$59+(Parametri!$B$60-Parametri!$B$59)/24*(B11-5))) -> 0.61666667 | M11: =L11*D11 -> 10.901172 | N11: =IF(B11<Parametri!$B$76,Parametri!$B$75*Parametri!$B$74*Parametri!$B$73/Parametri!$B$76,0) -> 0 | O11: =IF(B11<10,Parametri!$B$53,IF(B11<20,Parametri!$B$56,Parametri!$B$57))*M11*G11*Parametri!$B$72/1000 -> 3.1813727 | P11: =MIN(Parametri!$B$81+Parametri!$B$82, Parametri!$B$81+Parametri!$B$82*(B11+1)/Parametri!$B$83) -> 7.7 | Q11: =-IF(B11<10,Parametri!$B$51,IF(B11<20,Parametri!$B$54,Parametri!$B$57))*M11*G11/1000 -> -17.674293 | R11: =-Q11-Z11 -> 11.782862 | S11: =S10+R11 -> 64.473049 | T11: =-(Parametri!$B$86*(Parametri!$B$87*Parametri!$B$90+Parametri!$B$88*Parametri!$B$91+Parametri!$B$89*Parametri!$B$92)/1000000000)*MIN(B11+1,Parametri!$B$93) -> -2.85975 | U11: =IF(B11<Parametri!$B$125,Parametri!$B$46,IF(B11<Parametri!$B$126,Parametri!$B$47,Parametri!$B$48))*Parametri!$B$96*13/1000000000*((B11+1)*Parametri!$B$121+B11*(B11+1)/2*Parametri!$B$122) -> 11.206131 | V11: =IF(B11>=Parametri!$B$103-1,Parametri!$B$102*(1-Parametri!$B$127)^(B11-(Parametri!$B$103-1)),0) -> 5.4798495 | W11: =IF(B11>=Parametri!$B$105-1,Parametri!$B$104,0) -> 5 | X11: =IF(B11>=Parametri!$B$107-1,Parametri!$B$106+Parametri!$B$128*INT((B11-(Parametri!$B$107-1))/2),0) -> 3.03 | Y11: =IF(AND(B11>=Parametri!$B$109-1,B11<Parametri!$B$109-1+Parametri!$B$140),Parametri!$B$108,0) -> 0 | Z11: =IF(B11<10,Parametri!$B$52,IF(B11<20,Parametri!$B$55,0))*M11*G11/1000 -> 5.891431 | AA11: =Parametri!$B$159*Parametri!$B$160 -> 0 | AB11: =SUM(Z$5:Z11)+SUM(AA$5:AA11) -> 32.236525 | AC11: =-(Parametri!$B$67*SUM(Z$5:Z11)+Parametri!$B$161*SUM(AA$5:AA11)) -> -0.48354787 | AD11: =0 -> 0 | AE11: =Z11+AA11+N11+O11+P11+Q11+T11+U11+V11+W11+X11+Y11+AC11+AD11 -> 20.471194 | AF11: =AF10+AE11 -> 114.45918 | AG11: =-AF11/F11 -> -0.048777717 | AH11: =SUM(Z$5:Z11) -> 32.236525 | AI11: 0
A12: =Parametri!$B$6+B12 -> 2034 | B12: 7 | C12: =C11*(1+Parametri!$B$14) -> 23.253628 | D12: =D11*(1+Parametri!$B$15)+Parametri!$B$145*(1-Parametri!$B$15)^B11 -> 17.708713 | E12: =D12/C12 -> 0.76154622 | F12: =F11*(1+Parametri!$B$20) -> 2365.3189 | G12: =G11*(1+Parametri!$B$22) -> 27076.05 | H12: =F12*I12 -> 392.461 | I12: =IF(B12<=(Parametri!$B$35-Parametri!$B$6),Parametri!$B$32+(Parametri!$B$33-Parametri!$B$32)*B12/(Parametri!$B$35-Parametri!$B$6),Parametri!$B$33+(Parametri!$B$34-Parametri!$B$33)*(B12-(Parametri!$B$35-Parametri!$B$6))/(Parametri!$B$36-Parametri!$B$35)) -> 0.16592308 | J12: =H12-AE12 -> 369.32011 | K12: =J12/F12 -> 0.15613967 | L12: =IF(B12<=5,Parametri!$B$58+(Parametri!$B$59-Parametri!$B$58)/5*B12,MIN(Parametri!$B$60,Parametri!$B$59+(Parametri!$B$60-Parametri!$B$59)/24*(B12-5))) -> 0.63333333 | M12: =L12*D12 -> 11.215518 | N12: =IF(B12<Parametri!$B$76,Parametri!$B$75*Parametri!$B$74*Parametri!$B$73/Parametri!$B$76,0) -> 0 | O12: =IF(B12<10,Parametri!$B$53,IF(B12<20,Parametri!$B$56,Parametri!$B$57))*M12*G12*Parametri!$B$72/1000 -> 3.2796569 | P12: =MIN(Parametri!$B$81+Parametri!$B$82, Parametri!$B$81+Parametri!$B$82*(B12+1)/Parametri!$B$83) -> 8.3 | Q12: =-IF(B12<10,Parametri!$B$51,IF(B12<20,Parametri!$B$54,Parametri!$B$57))*M12*G12/1000 -> -18.220316 | R12: =-Q12-Z12 -> 12.146877 | S12: =S11+R12 -> 76.619927 | T12: =-(Parametri!$B$86*(Parametri!$B$87*Parametri!$B$90+Parametri!$B$88*Parametri!$B$91+Parametri!$B$89*Parametri!$B$92)/1000000000)*MIN(B12+1,Parametri!$B$93) -> -2.85975 | U12: =IF(B12<Parametri!$B$125,Parametri!$B$46,IF(B12<Parametri!$B$126,Parametri!$B$47,Parametri!$B$48))*Parametri!$B$96*13/1000000000*((B12+1)*Parametri!$B$121+B12*(B12+1)/2*Parametri!$B$122) -> 13.574855 | V12: =IF(B12>=Parametri!$B$103-1,Parametri!$B$102*(1-Parametri!$B$127)^(B12-(Parametri!$B$103-1)),0) -> 5.3976518 | W12: =IF(B12>=Parametri!$B$105-1,Parametri!$B$104,0) -> 5 | X12: =IF(B12>=Parametri!$B$107-1,Parametri!$B$106+Parametri!$B$128*INT((B12-(Parametri!$B$107-1))/2),0) -> 3.17 | Y12: =IF(AND(B12>=Parametri!$B$109-1,B12<Parametri!$B$109-1+Parametri!$B$140),Parametri!$B$108,0) -> 0 | Z12: =IF(B12<10,Parametri!$B$52,IF(B12<20,Parametri!$B$55,0))*M12*G12/1000 -> 6.0734387 | AA12: =Parametri!$B$159*Parametri!$B$160 -> 0 | AB12: =SUM(Z$5:Z12)+SUM(AA$5:AA12) -> 38.309963 | AC12: =-(Parametri!$B$67*SUM(Z$5:Z12)+Parametri!$B$161*SUM(AA$5:AA12)) -> -0.57464945 | AD12: =0 -> 0 | AE12: =Z12+AA12+N12+O12+P12+Q12+T12+U12+V12+W12+X12+Y12+AC12+AD12 -> 23.140887 | AF12: =AF11+AE12 -> 137.60007 | AG12: =-AF12/F12 -> -0.058174003 | AH12: =SUM(Z$5:Z12) -> 38.309963 | AI12: 0
A13: =Parametri!$B$6+B13 -> 2035 | B13: 8 | C13: =C12*(1+Parametri!$B$14) -> 23.39315 | D13: =D12*(1+Parametri!$B$15)+Parametri!$B$145*(1-Parametri!$B$15)^B12 -> 17.740291 | E13: =D13/C13 -> 0.75835407 | F13: =F12*(1+Parametri!$B$20) -> 2384.2415 | G13: =G12*(1+Parametri!$B$22) -> 27130.202 | H13: =F13*I13 -> 397.61812 | I13: =IF(B13<=(Parametri!$B$35-Parametri!$B$6),Parametri!$B$32+(Parametri!$B$33-Parametri!$B$32)*B13/(Parametri!$B$35-Parametri!$B$6),Parametri!$B$33+(Parametri!$B$34-Parametri!$B$33)*(B13-(Parametri!$B$35-Parametri!$B$6))/(Parametri!$B$36-Parametri!$B$35)) -> 0.16676923 | J13: =H13-AE13 -> 371.75917 | K13: =J13/F13 -> 0.15592346 | L13: =IF(B13<=5,Parametri!$B$58+(Parametri!$B$59-Parametri!$B$58)/5*B13,MIN(Parametri!$B$60,Parametri!$B$59+(Parametri!$B$60-Parametri!$B$59)/24*(B13-5))) -> 0.65 | M13: =L13*D13 -> 11.531189 | N13: =IF(B13<Parametri!$B$76,Parametri!$B$75*Parametri!$B$74*Parametri!$B$73/Parametri!$B$76,0) -> 0 | O13: =IF(B13<10,Parametri!$B$53,IF(B13<20,Parametri!$B$56,Parametri!$B$57))*M13*G13*Parametri!$B$72/1000 -> 3.3787097 | P13: =MIN(Parametri!$B$81+Parametri!$B$82, Parametri!$B$81+Parametri!$B$82*(B13+1)/Parametri!$B$83) -> 8.9 | Q13: =-IF(B13<10,Parametri!$B$51,IF(B13<20,Parametri!$B$54,Parametri!$B$57))*M13*G13/1000 -> -18.770609 | R13: =-Q13-Z13 -> 12.51374 | S13: =S12+R13 -> 89.133666 | T13: =-(Parametri!$B$86*(Parametri!$B$87*Parametri!$B$90+Parametri!$B$88*Parametri!$B$91+Parametri!$B$89*Parametri!$B$92)/1000000000)*MIN(B13+1,Parametri!$B$93) -> -2.85975 | U13: =IF(B13<Parametri!$B$125,Parametri!$B$46,IF(B13<Parametri!$B$126,Parametri!$B$47,Parametri!$B$48))*Parametri!$B$96*13/1000000000*((B13+1)*Parametri!$B$121+B13*(B13+1)/2*Parametri!$B$122) -> 16.13554 | V13: =IF(B13>=Parametri!$B$103-1,Parametri!$B$102*(1-Parametri!$B$127)^(B13-(Parametri!$B$103-1)),0) -> 5.316687 | W13: =IF(B13>=Parametri!$B$105-1,Parametri!$B$104,0) -> 5 | X13: =IF(B13>=Parametri!$B$107-1,Parametri!$B$106+Parametri!$B$128*INT((B13-(Parametri!$B$107-1))/2),0) -> 3.17 | Y13: =IF(AND(B13>=Parametri!$B$109-1,B13<Parametri!$B$109-1+Parametri!$B$140),Parametri!$B$108,0) -> 0 | Z13: =IF(B13<10,Parametri!$B$52,IF(B13<20,Parametri!$B$55,0))*M13*G13/1000 -> 6.2568698 | AA13: =Parametri!$B$159*Parametri!$B$160 -> 0 | AB13: =SUM(Z$5:Z13)+SUM(AA$5:AA13) -> 44.566833 | AC13: =-(Parametri!$B$67*SUM(Z$5:Z13)+Parametri!$B$161*SUM(AA$5:AA13)) -> -0.6685025 | AD13: =0 -> 0 | AE13: =Z13+AA13+N13+O13+P13+Q13+T13+U13+V13+W13+X13+Y13+AC13+AD13 -> 25.858945 | AF13: =AF12+AE13 -> 163.45902 | AG13: =-AF13/F13 -> -0.068558079 | AH13: =SUM(Z$5:Z13) -> 44.566833 | AI13: 0
A14: =Parametri!$B$6+B14 -> 2036 | B14: 9 | C14: =C13*(1+Parametri!$B$14) -> 23.533509 | D14: =D13*(1+Parametri!$B$15)+Parametri!$B$145*(1-Parametri!$B$15)^B13 -> 17.772311 | E14: =D14/C14 -> 0.75519172 | F14: =F13*(1+Parametri!$B$20) -> 2403.3154 | G14: =G13*(1+Parametri!$B$22) -> 27184.463 | H14: =F14*I14 -> 402.83264 | I14: =IF(B14<=(Parametri!$B$35-Parametri!$B$6),Parametri!$B$32+(Parametri!$B$33-Parametri!$B$32)*B14/(Parametri!$B$35-Parametri!$B$6),Parametri!$B$33+(Parametri!$B$34-Parametri!$B$33)*(B14-(Parametri!$B$35-Parametri!$B$6))/(Parametri!$B$36-Parametri!$B$35)) -> 0.16761538 | J14: =H14-AE14 -> 373.92734 | K14: =J14/F14 -> 0.15558812 | L14: =IF(B14<=5,Parametri!$B$58+(Parametri!$B$59-Parametri!$B$58)/5*B14,MIN(Parametri!$B$60,Parametri!$B$59+(Parametri!$B$60-Parametri!$B$59)/24*(B14-5))) -> 0.66666667 | M14: =L14*D14 -> 11.848207 | N14: =IF(B14<Parametri!$B$76,Parametri!$B$75*Parametri!$B$74*Parametri!$B$73/Parametri!$B$76,0) -> 0 | O14: =IF(B14<10,Parametri!$B$53,IF(B14<20,Parametri!$B$56,Parametri!$B$57))*M14*G14*Parametri!$B$72/1000 -> 3.4785413 | P14: =MIN(Parametri!$B$81+Parametri!$B$82, Parametri!$B$81+Parametri!$B$82*(B14+1)/Parametri!$B$83) -> 9.5 | Q14: =-IF(B14<10,Parametri!$B$51,IF(B14<20,Parametri!$B$54,Parametri!$B$57))*M14*G14/1000 -> -19.325229 | R14: =-Q14-Z14 -> 12.883486 | S14: =S13+R14 -> 102.01715 | T14: =-(Parametri!$B$86*(Parametri!$B$87*Parametri!$B$90+Parametri!$B$88*Parametri!$B$91+Parametri!$B$89*Parametri!$B$92)/1000000000)*MIN(B14+1,Parametri!$B$93) -> -2.85975 | U14: =IF(B14<Parametri!$B$125,Parametri!$B$46,IF(B14<Parametri!$B$126,Parametri!$B$47,Parametri!$B$48))*Parametri!$B$96*13/1000000000*((B14+1)*Parametri!$B$121+B14*(B14+1)/2*Parametri!$B$122) -> 18.888187 | V14: =IF(B14>=Parametri!$B$103-1,Parametri!$B$102*(1-Parametri!$B$127)^(B14-(Parametri!$B$103-1)),0) -> 5.2369367 | W14: =IF(B14>=Parametri!$B$105-1,Parametri!$B$104,0) -> 5 | X14: =IF(B14>=Parametri!$B$107-1,Parametri!$B$106+Parametri!$B$128*INT((B14-(Parametri!$B$107-1))/2),0) -> 3.31 | Y14: =IF(AND(B14>=Parametri!$B$109-1,B14<Parametri!$B$109-1+Parametri!$B$140),Parametri!$B$108,0) -> 0 | Z14: =IF(B14<10,Parametri!$B$52,IF(B14<20,Parametri!$B$55,0))*M14*G14/1000 -> 6.4417431 | AA14: =Parametri!$B$159*Parametri!$B$160 -> 0 | AB14: =SUM(Z$5:Z14)+SUM(AA$5:AA14) -> 51.008576 | AC14: =-(Parametri!$B$67*SUM(Z$5:Z14)+Parametri!$B$161*SUM(AA$5:AA14)) -> -0.76512864 | AD14: =0 -> 0 | AE14: =Z14+AA14+N14+O14+P14+Q14+T14+U14+V14+W14+X14+Y14+AC14+AD14 -> 28.905301 | AF14: =AF13+AE14 -> 192.36432 | AG14: =-AF14/F14 -> -0.080041228 | AH14: =SUM(Z$5:Z14) -> 51.008576 | AI14: 0
A15: =Parametri!$B$6+B15 -> 2037 | B15: 10 | C15: =C14*(1+Parametri!$B$14) -> 23.67471 | D15: =D14*(1+Parametri!$B$15)+Parametri!$B$145*(1-Parametri!$B$15)^B14 -> 17.804775 | E15: =D15/C15 -> 0.75205885 | F15: =F14*(1+Parametri!$B$20) -> 2422.5419 | G15: =G14*(1+Parametri!$B$22) -> 27238.832 | H15: =F15*I15 -> 408.10514 | I15: =IF(B15<=(Parametri!$B$35-Parametri!$B$6),Parametri!$B$32+(Parametri!$B$33-Parametri!$B$32)*B15/(Parametri!$B$35-Parametri!$B$6),Parametri!$B$33+(Parametri!$B$34-Parametri!$B$33)*(B15-(Parametri!$B$35-Parametri!$B$6))/(Parametri!$B$36-Parametri!$B$35)) -> 0.16846154 | J15: =H15-AE15 -> 380.94375 | K15: =J15/F15 -> 0.1572496 | L15: =IF(B15<=5,Parametri!$B$58+(Parametri!$B$59-Parametri!$B$58)/5*B15,MIN(Parametri!$B$60,Parametri!$B$59+(Parametri!$B$60-Parametri!$B$59)/24*(B15-5))) -> 0.68333333 | M15: =L15*D15 -> 12.166596 | N15: =IF(B15<Parametri!$B$76,Parametri!$B$75*Parametri!$B$74*Parametri!$B$73/Parametri!$B$76,0) -> 0 | O15: =IF(B15<10,Parametri!$B$53,IF(B15<20,Parametri!$B$56,Parametri!$B$57))*M15*G15*Parametri!$B$72/1000 -> 5.3687428 | P15: =MIN(Parametri!$B$81+Parametri!$B$82, Parametri!$B$81+Parametri!$B$82*(B15+1)/Parametri!$B$83) -> 10.1 | Q15: =-IF(B15<10,Parametri!$B$51,IF(B15<20,Parametri!$B$54,Parametri!$B$57))*M15*G15/1000 -> -26.51231 | R15: =-Q15-Z15 -> 19.884232 | S15: =S14+R15 -> 121.90139 | T15: =-(Parametri!$B$86*(Parametri!$B$87*Parametri!$B$90+Parametri!$B$88*Parametri!$B$91+Parametri!$B$89*Parametri!$B$92)/1000000000)*MIN(B15+1,Parametri!$B$93) -> -2.85975 | U15: =IF(B15<Parametri!$B$125,Parametri!$B$46,IF(B15<Parametri!$B$126,Parametri!$B$47,Parametri!$B$48))*Parametri!$B$96*13/1000000000*((B15+1)*Parametri!$B$121+B15*(B15+1)/2*Parametri!$B$122) -> 21.832797 | V15: =IF(B15>=Parametri!$B$103-1,Parametri!$B$102*(1-Parametri!$B$127)^(B15-(Parametri!$B$103-1)),0) -> 5.1583827 | W15: =IF(B15>=Parametri!$B$105-1,Parametri!$B$104,0) -> 5 | X15: =IF(B15>=Parametri!$B$107-1,Parametri!$B$106+Parametri!$B$128*INT((B15-(Parametri!$B$107-1))/2),0) -> 3.31 | Y15: =IF(AND(B15>=Parametri!$B$109-1,B15<Parametri!$B$109-1+Parametri!$B$140),Parametri!$B$108,0) -> 0 | Z15: =IF(B15<10,Parametri!$B$52,IF(B15<20,Parametri!$B$55,0))*M15*G15/1000 -> 6.6280775 | AA15: =Parametri!$B$159*Parametri!$B$160 -> 0 | AB15: =SUM(Z$5:Z15)+SUM(AA$5:AA15) -> 57.636654 | AC15: =-(Parametri!$B$67*SUM(Z$5:Z15)+Parametri!$B$161*SUM(AA$5:AA15)) -> -0.86454981 | AD15: =0 -> 0 | AE15: =Z15+AA15+N15+O15+P15+Q15+T15+U15+V15+W15+X15+Y15+AC15+AD15 -> 27.16139 | AF15: =AF14+AE15 -> 219.52571 | AG15: =-AF15/F15 -> -0.090617918 | AH15: =SUM(Z$5:Z15) -> 57.636654 | AI15: 0
A16: =Parametri!$B$6+B16 -> 2038 | B16: 11 | C16: =C15*(1+Parametri!$B$14) -> 23.816758 | D16: =D15*(1+Parametri!$B$15)+Parametri!$B$145*(1-Parametri!$B$15)^B15 -> 17.837684 | E16: =D16/C16 -> 0.74895514 | F16: =F15*(1+Parametri!$B$20) -> 2441.9223 | G16: =G15*(1+Parametri!$B$22) -> 27293.309 | H16: =F16*I16 -> 413.43623 | I16: =IF(B16<=(Parametri!$B$35-Parametri!$B$6),Parametri!$B$32+(Parametri!$B$33-Parametri!$B$32)*B16/(Parametri!$B$35-Parametri!$B$6),Parametri!$B$33+(Parametri!$B$34-Parametri!$B$33)*(B16-(Parametri!$B$35-Parametri!$B$6))/(Parametri!$B$36-Parametri!$B$35)) -> 0.16930769 | J16: =H16-AE16 -> 387.98307 | K16: =J16/F16 -> 0.15888428 | L16: =IF(B16<=5,Parametri!$B$58+(Parametri!$B$59-Parametri!$B$58)/5*B16,MIN(Parametri!$B$60,Parametri!$B$59+(Parametri!$B$60-Parametri!$B$59)/24*(B16-5))) -> 0.7 | M16: =L16*D16 -> 12.486379 | N16: =IF(B16<Parametri!$B$76,Parametri!$B$75*Parametri!$B$74*Parametri!$B$73/Parametri!$B$76,0) -> 0 | O16: =IF(B16<10,Parametri!$B$53,IF(B16<20,Parametri!$B$56,Parametri!$B$57))*M16*G16*Parametri!$B$72/1000 -> 5.5208724 | P16: =MIN(Parametri!$B$81+Parametri!$B$82, Parametri!$B$81+Parametri!$B$82*(B16+1)/Parametri!$B$83) -> 10.7 | Q16: =-IF(B16<10,Parametri!$B$51,IF(B16<20,Parametri!$B$54,Parametri!$B$57))*M16*G16/1000 -> -27.263567 | R16: =-Q16-Z16 -> 20.447676 | S16: =S15+R16 -> 142.34906 | T16: =-(Parametri!$B$86*(Parametri!$B$87*Parametri!$B$90+Parametri!$B$88*Parametri!$B$91+Parametri!$B$89*Parametri!$B$92)/1000000000)*MIN(B16+1,Parametri!$B$93) -> -2.85975 | U16: =IF(B16<Parametri!$B$125,Parametri!$B$46,IF(B16<Parametri!$B$126,Parametri!$B$47,Parametri!$B$48))*Parametri!$B$96*13/1000000000*((B16+1)*Parametri!$B$121+B16*(B16+1)/2*Parametri!$B$122) -> 19.975494 | V16: =IF(B16>=Parametri!$B$103-1,Parametri!$B$102*(1-Parametri!$B$127)^(B16-(Parametri!$B$103-1)),0) -> 5.0810069 | W16: =IF(B16>=Parametri!$B$105-1,Parametri!$B$104,0) -> 5 | X16: =IF(B16>=Parametri!$B$107-1,Parametri!$B$106+Parametri!$B$128*INT((B16-(Parametri!$B$107-1))/2),0) -> 3.45 | Y16: =IF(AND(B16>=Parametri!$B$109-1,B16<Parametri!$B$109-1+Parametri!$B$140),Parametri!$B$108,0) -> 0 | Z16: =IF(B16<10,Parametri!$B$52,IF(B16<20,Parametri!$B$55,0))*M16*G16/1000 -> 6.8158919 | AA16: =Parametri!$B$159*Parametri!$B$160 -> 0 | AB16: =SUM(Z$5:Z16)+SUM(AA$5:AA16) -> 64.452546 | AC16: =-(Parametri!$B$67*SUM(Z$5:Z16)+Parametri!$B$161*SUM(AA$5:AA16)) -> -0.96678818 | AD16: =0 -> 0 | AE16: =Z16+AA16+N16+O16+P16+Q16+T16+U16+V16+W16+X16+Y16+AC16+AD16 -> 25.45316 | AF16: =AF15+AE16 -> 244.97887 | AG16: =-AF16/F16 -> -0.10032214 | AH16: =SUM(Z$5:Z16) -> 64.452546 | AI16: 0
A17: =Parametri!$B$6+B17 -> 2039 | B17: 12 | C17: =C16*(1+Parametri!$B$14) -> 23.959659 | D17: =D16*(1+Parametri!$B$15)+Parametri!$B$145*(1-Parametri!$B$15)^B16 -> 17.871037 | E17: =D17/C17 -> 0.74588028 | F17: =F16*(1+Parametri!$B$20) -> 2461.4577 | G17: =G16*(1+Parametri!$B$22) -> 27347.896 | H17: =F17*I17 -> 418.82649 | I17: =IF(B17<=(Parametri!$B$35-Parametri!$B$6),Parametri!$B$32+(Parametri!$B$33-Parametri!$B$32)*B17/(Parametri!$B$35-Parametri!$B$6),Parametri!$B$33+(Parametri!$B$34-Parametri!$B$33)*(B17-(Parametri!$B$35-Parametri!$B$6))/(Parametri!$B$36-Parametri!$B$35)) -> 0.17015385 | J17: =H17-AE17 -> 390.70639 | K17: =J17/F17 -> 0.15872968 | L17: =IF(B17<=5,Parametri!$B$58+(Parametri!$B$59-Parametri!$B$58)/5*B17,MIN(Parametri!$B$60,Parametri!$B$59+(Parametri!$B$60-Parametri!$B$59)/24*(B17-5))) -> 0.71666667 | M17: =L17*D17 -> 12.807577 | N17: =IF(B17<Parametri!$B$76,Parametri!$B$75*Parametri!$B$74*Parametri!$B$73/Parametri!$B$76,0) -> 0 | O17: =IF(B17<10,Parametri!$B$53,IF(B17<20,Parametri!$B$56,Parametri!$B$57))*M17*G17*Parametri!$B$72/1000 -> 5.6742164 | P17: =MIN(Parametri!$B$81+Parametri!$B$82, Parametri!$B$81+Parametri!$B$82*(B17+1)/Parametri!$B$83) -> 11.3 | Q17: =-IF(B17<10,Parametri!$B$51,IF(B17<20,Parametri!$B$54,Parametri!$B$57))*M17*G17/1000 -> -28.020822 | R17: =-Q17-Z17 -> 21.015616 | S17: =S16+R17 -> 163.36468 | T17: =-(Parametri!$B$86*(Parametri!$B$87*Parametri!$B$90+Parametri!$B$88*Parametri!$B$91+Parametri!$B$89*Parametri!$B$92)/1000000000)*MIN(B17+1,Parametri!$B$93) -> -2.85975 | U17: =IF(B17<Parametri!$B$125,Parametri!$B$46,IF(B17<Parametri!$B$126,Parametri!$B$47,Parametri!$B$48))*Parametri!$B$96*13/1000000000*((B17+1)*Parametri!$B$121+B17*(B17+1)/2*Parametri!$B$122) -> 22.638321 | V17: =IF(B17>=Parametri!$B$103-1,Parametri!$B$102*(1-Parametri!$B$127)^(B17-(Parametri!$B$103-1)),0) -> 5.0047918 | W17: =IF(B17>=Parametri!$B$105-1,Parametri!$B$104,0) -> 5 | X17: =IF(B17>=Parametri!$B$107-1,Parametri!$B$106+Parametri!$B$128*INT((B17-(Parametri!$B$107-1))/2),0) -> 3.45 | Y17: =IF(AND(B17>=Parametri!$B$109-1,B17<Parametri!$B$109-1+Parametri!$B$140),Parametri!$B$108,0) -> 0 | Z17: =IF(B17<10,Parametri!$B$52,IF(B17<20,Parametri!$B$55,0))*M17*G17/1000 -> 7.0052055 | AA17: =Parametri!$B$159*Parametri!$B$160 -> 0 | AB17: =SUM(Z$5:Z17)+SUM(AA$5:AA17) -> 71.457751 | AC17: =-(Parametri!$B$67*SUM(Z$5:Z17)+Parametri!$B$161*SUM(AA$5:AA17)) -> -1.0718663 | AD17: =0 -> 0 | AE17: =Z17+AA17+N17+O17+P17+Q17+T17+U17+V17+W17+X17+Y17+AC17+AD17 -> 28.120096 | AF17: =AF16+AE17 -> 273.09896 | AG17: =-AF17/F17 -> -0.1109501 | AH17: =SUM(Z$5:Z17) -> 71.457751 | AI17: 0
... A19: =Parametri!$B$6+B19 -> 2041 | B19: 14 | C19: =C18*(1+Parametri!$B$14) -> 24.248037 | D19: =D18*(1+Parametri!$B$15)+Parametri!$B$145*(1-Parametri!$B$15)^B18 -> 17.939083 | E19: =D19/C19 -> 0.73981587 | F19: =F18*(1+Parametri!$B$20) -> 2500.9985 | G19: =G18*(1+Parametri!$B$22) -> 27457.397 | H19: =F19*I19 -> 423.91925 | I19: =IF(B19<=(Parametri!$B$35-Parametri!$B$6),Parametri!$B$32+(Parametri!$B$33-Parametri!$B$32)*B19/(Parametri!$B$35-Parametri!$B$6),Parametri!$B$33+(Parametri!$B$34-Parametri!$B$33)*(B19-(Parametri!$B$35-Parametri!$B$6))/(Parametri!$B$36-Parametri!$B$35)) -> 0.1695 | J19: =H19-AE19 -> 389.87979 | K19: =J19/F19 -> 0.15588965 | L19: =IF(B19<=5,Parametri!$B$58+(Parametri!$B$59-Parametri!$B$58)/5*B19,MIN(Parametri!$B$60,Parametri!$B$59+(Parametri!$B$60-Parametri!$B$59)/24*(B19-5))) -> 0.75 | M19: =L19*D19 -> 13.454312 | N19: =IF(B19<Parametri!$B$76,Parametri!$B$75*Parametri!$B$74*Parametri!$B$73/Parametri!$B$76,0) -> 0 | O19: =IF(B19<10,Parametri!$B$53,IF(B19<20,Parametri!$B$56,Parametri!$B$57))*M19*G19*Parametri!$B$72/1000 -> 5.9846103 | P19: =MIN(Parametri!$B$81+Parametri!$B$82, Parametri!$B$81+Parametri!$B$82*(B19+1)/Parametri!$B$83) -> 12.5 | Q19: =-IF(B19<10,Parametri!$B$51,IF(B19<20,Parametri!$B$54,Parametri!$B$57))*M19*G19/1000 -> -29.553631 | R19: =-Q19-Z19 -> 22.165223 | S19: =S18+R19 -> 207.11801 | T19: =-(Parametri!$B$86*(Parametri!$B$87*Parametri!$B$90+Parametri!$B$88*Parametri!$B$91+Parametri!$B$89*Parametri!$B$92)/1000000000)*MIN(B19+1,Parametri!$B$93) -> -2.85975 | U19: =IF(B19<Parametri!$B$125,Parametri!$B$46,IF(B19<Parametri!$B$126,Parametri!$B$47,Parametri!$B$48))*Parametri!$B$96*13/1000000000*((B19+1)*Parametri!$B$121+B19*(B19+1)/2*Parametri!$B$122) -> 28.424682 | V19: =IF(B19>=Parametri!$B$103-1,Parametri!$B$102*(1-Parametri!$B$127)^(B19-(Parametri!$B$103-1)),0) -> 4.8557741 | W19: =IF(B19>=Parametri!$B$105-1,Parametri!$B$104,0) -> 5 | X19: =IF(B19>=Parametri!$B$107-1,Parametri!$B$106+Parametri!$B$128*INT((B19-(Parametri!$B$107-1))/2),0) -> 3.59 | Y19: =IF(AND(B19>=Parametri!$B$109-1,B19<Parametri!$B$109-1+Parametri!$B$140),Parametri!$B$108,0) -> 0 | Z19: =IF(B19<10,Parametri!$B$52,IF(B19<20,Parametri!$B$55,0))*M19*G19/1000 -> 7.3884078 | AA19: =Parametri!$B$159*Parametri!$B$160 -> 0 | AB19: =SUM(Z$5:Z19)+SUM(AA$5:AA19) -> 86.042197 | AC19: =-(Parametri!$B$67*SUM(Z$5:Z19)+Parametri!$B$161*SUM(AA$5:AA19)) -> -1.2906329 | AD19: =0 -> 0 | AE19: =Z19+AA19+N19+O19+P19+Q19+T19+U19+V19+W19+X19+Y19+AC19+AD19 -> 34.03946 | AF19: =AF18+AE19 -> 338.21398 | AG19: =-AF19/F19 -> -0.13523158 | AH19: =SUM(Z$5:Z19) -> 86.042197 | AI19: 0
A20: =Parametri!$B$6+B20 -> 2042 | B20: 15 | C20: =C19*(1+Parametri!$B$14) -> 24.393526 | D20: =D19*(1+Parametri!$B$15)+Parametri!$B$145*(1-Parametri!$B$15)^B19 -> 17.973777 | E20: =D20/C20 -> 0.7368257 | F20: =F19*(1+Parametri!$B$20) -> 2521.0065 | G20: =G19*(1+Parametri!$B$22) -> 27512.312 | H20: =F20*I20 -> 423.52909 | I20: =IF(B20<=(Parametri!$B$35-Parametri!$B$6),Parametri!$B$32+(Parametri!$B$33-Parametri!$B$32)*B20/(Parametri!$B$35-Parametri!$B$6),Parametri!$B$33+(Parametri!$B$34-Parametri!$B$33)*(B20-(Parametri!$B$35-Parametri!$B$6))/(Parametri!$B$36-Parametri!$B$35)) -> 0.168 | J20: =H20-AE20 -> 389.92122 | K20: =J20/F20 -> 0.15466887 | L20: =IF(B20<=5,Parametri!$B$58+(Parametri!$B$59-Parametri!$B$58)/5*B20,MIN(Parametri!$B$60,Parametri!$B$59+(Parametri!$B$60-Parametri!$B$59)/24*(B20-5))) -> 0.76666667 | M20: =L20*D20 -> 13.779895 | N20: =IF(B20<Parametri!$B$76,Parametri!$B$75*Parametri!$B$74*Parametri!$B$73/Parametri!$B$76,0) -> 0 | O20: =IF(B20<10,Parametri!$B$53,IF(B20<20,Parametri!$B$56,Parametri!$B$57))*M20*G20*Parametri!$B$72/1000 -> 6.1416918 | P20: =MIN(Parametri!$B$81+Parametri!$B$82, Parametri!$B$81+Parametri!$B$82*(B20+1)/Parametri!$B$83) -> 12.5 | Q20: =-IF(B20<10,Parametri!$B$51,IF(B20<20,Parametri!$B$54,Parametri!$B$57))*M20*G20/1000 -> -30.329342 | R20: =-Q20-Z20 -> 22.747007 | S20: =S19+R20 -> 229.86502 | T20: =-(Parametri!$B$86*(Parametri!$B$87*Parametri!$B$90+Parametri!$B$88*Parametri!$B$91+Parametri!$B$89*Parametri!$B$92)/1000000000)*MIN(B20+1,Parametri!$B$93) -> -2.85975 | U20: =IF(B20<Parametri!$B$125,Parametri!$B$46,IF(B20<Parametri!$B$126,Parametri!$B$47,Parametri!$B$48))*Parametri!$B$96*13/1000000000*((B20+1)*Parametri!$B$121+B20*(B20+1)/2*Parametri!$B$122) -> 31.548217 | V20: =IF(B20>=Parametri!$B$103-1,Parametri!$B$102*(1-Parametri!$B$127)^(B20-(Parametri!$B$103-1)),0) -> 4.7829375 | W20: =IF(B20>=Parametri!$B$105-1,Parametri!$B$104,0) -> 5 | X20: =IF(B20>=Parametri!$B$107-1,Parametri!$B$106+Parametri!$B$128*INT((B20-(Parametri!$B$107-1))/2),0) -> 3.73 | Y20: =IF(AND(B20>=Parametri!$B$109-1,B20<Parametri!$B$109-1+Parametri!$B$140),Parametri!$B$108,0) -> 0 | Z20: =IF(B20<10,Parametri!$B$52,IF(B20<20,Parametri!$B$55,0))*M20*G20/1000 -> 7.5823356 | AA20: =Parametri!$B$159*Parametri!$B$160 -> 0 | AB20: =(SUM(Z$5:Z20)+SUM(AA$5:AA20)-SUM(Z$5:Z5)-SUM(AA$5:AA5)) -> 90.540682 | AC20: =-(Parametri!$B$67*SUM(Z$5:Z20)+Parametri!$B$161*SUM(AA$5:AA20)) -> -1.404368 | AD20: =-Z5-AA5 -> -3.08385 | AE20: =Z20+AA20+N20+O20+P20+Q20+T20+U20+V20+W20+X20+Y20+AC20+AD20 -> 33.607872 | AF20: =AF19+AE20 -> 371.82185 | AG20: =-AF20/F20 -> -0.14748945 | AH20: =SUM(Z$5:Z20)-SUM(Z$5:Z5) -> 90.540682 | AI20: =-Z5 -> -3.08385
A21: =Parametri!$B$6+B21 -> 2043 | B21: 16 | C21: =C20*(1+Parametri!$B$14) -> 24.539887 | D21: =D20*(1+Parametri!$B$15)+Parametri!$B$145*(1-Parametri!$B$15)^B20 -> 18.008919 | E21: =D21/C21 -> 0.73386317 | F21: =F20*(1+Parametri!$B$20) -> 2541.1746 | G21: =G20*(1+Parametri!$B$22) -> 27567.336 | H21: =F21*I21 -> 423.10556 | I21: =IF(B21<=(Parametri!$B$35-Parametri!$B$6),Parametri!$B$32+(Parametri!$B$33-Parametri!$B$32)*B21/(Parametri!$B$35-Parametri!$B$6),Parametri!$B$33+(Parametri!$B$34-Parametri!$B$33)*(B21-(Parametri!$B$35-Parametri!$B$6))/(Parametri!$B$36-Parametri!$B$35)) -> 0.1665 | J21: =H21-AE21 -> 387.35482 | K21: =J21/F21 -> 0.15243141 | L21: =IF(B21<=5,Parametri!$B$58+(Parametri!$B$59-Parametri!$B$58)/5*B21,MIN(Parametri!$B$60,Parametri!$B$59+(Parametri!$B$60-Parametri!$B$59)/24*(B21-5))) -> 0.78333333 | M21: =L21*D21 -> 14.106987 | N21: =IF(B21<Parametri!$B$76,Parametri!$B$75*Parametri!$B$74*Parametri!$B$73/Parametri!$B$76,0) -> 0 | O21: =IF(B21<10,Parametri!$B$53,IF(B21<20,Parametri!$B$56,Parametri!$B$57))*M21*G21*Parametri!$B$72/1000 -> 6.3000511 | P21: =MIN(Parametri!$B$81+Parametri!$B$82, Parametri!$B$81+Parametri!$B$82*(B21+1)/Parametri!$B$83) -> 12.5 | Q21: =-IF(B21<10,Parametri!$B$51,IF(B21<20,Parametri!$B$54,Parametri!$B$57))*M21*G21/1000 -> -31.111363 | R21: =-Q21-Z21 -> 23.333523 | S21: =S20+R21 -> 253.19854 | T21: =-(Parametri!$B$86*(Parametri!$B$87*Parametri!$B$90+Parametri!$B$88*Parametri!$B$91+Parametri!$B$89*Parametri!$B$92)/1000000000)*MIN(B21+1,Parametri!$B$93) -> -2.85975 | U21: =IF(B21<Parametri!$B$125,Parametri!$B$46,IF(B21<Parametri!$B$126,Parametri!$B$47,Parametri!$B$48))*Parametri!$B$96*13/1000000000*((B21+1)*Parametri!$B$121+B21*(B21+1)/2*Parametri!$B$122) -> 34.825321 | V21: =IF(B21>=Parametri!$B$103-1,Parametri!$B$102*(1-Parametri!$B$127)^(B21-(Parametri!$B$103-1)),0) -> 4.7111935 | W21: =IF(B21>=Parametri!$B$105-1,Parametri!$B$104,0) -> 5 | X21: =IF(B21>=Parametri!$B$107-1,Parametri!$B$106+Parametri!$B$128*INT((B21-(Parametri!$B$107-1))/2),0) -> 3.73 | Y21: =IF(AND(B21>=Parametri!$B$109-1,B21<Parametri!$B$109-1+Parametri!$B$140),Parametri!$B$108,0) -> 0 | Z21: =IF(B21<10,Parametri!$B$52,IF(B21<20,Parametri!$B$55,0))*M21*G21/1000 -> 7.7778409 | AA21: =Parametri!$B$159*Parametri!$B$160 -> 0 | AB21: =(SUM(Z$5:Z21)+SUM(AA$5:AA21)-SUM(Z$5:Z6)-SUM(AA$5:AA6)) -> 94.71701 | AC21: =-(Parametri!$B$67*SUM(Z$5:Z21)+Parametri!$B$161*SUM(AA$5:AA21)) -> -1.5210356 | AD21: =-Z6-AA6 -> -3.6015127 | AE21: =Z21+AA21+N21+O21+P21+Q21+T21+U21+V21+W21+X21+Y21+AC21+AD21 -> 35.750745 | AF21: =AF20+AE21 -> 407.5726 | AG21: =-AF21/F21 -> -0.16038749 | AH21: =SUM(Z$5:Z21)-SUM(Z$5:Z6) -> 94.71701 | AI21: =-Z6 -> -3.6015127
A22: =Parametri!$B$6+B22 -> 2044 | B22: 17 | C22: =C21*(1+Parametri!$B$14) -> 24.687126 | D22: =D21*(1+Parametri!$B$15)+Parametri!$B$145*(1-Parametri!$B$15)^B21 -> 18.044511 | E22: =D22/C22 -> 0.73092796 | F22: =F21*(1+Parametri!$B$20) -> 2561.504 | G22: =G21*(1+Parametri!$B$22) -> 27622.471 | H22: =F22*I22 -> 422.64815 | I22: =IF(B22<=(Parametri!$B$35-Parametri!$B$6),Parametri!$B$32+(Parametri!$B$33-Parametri!$B$32)*B22/(Parametri!$B$35-Parametri!$B$6),Parametri!$B$33+(Parametri!$B$34-Parametri!$B$33)*(B22-(Parametri!$B$35-Parametri!$B$6))/(Parametri!$B$36-Parametri!$B$35)) -> 0.165 | J22: =H22-AE22 -> 384.47015 | K22: =J22/F22 -> 0.15009548 | L22: =IF(B22<=5,Parametri!$B$58+(Parametri!$B$59-Parametri!$B$58)/5*B22,MIN(Parametri!$B$60,Parametri!$B$59+(Parametri!$B$60-Parametri!$B$59)/24*(B22-5))) -> 0.8 | M22: =L22*D22 -> 14.435609 | N22: =IF(B22<Parametri!$B$76,Parametri!$B$75*Parametri!$B$74*Parametri!$B$73/Parametri!$B$76,0) -> 0 | O22: =IF(B22<10,Parametri!$B$53,IF(B22<20,Parametri!$B$56,Parametri!$B$57))*M22*G22*Parametri!$B$72/1000 -> 6.4597043 | P22: =MIN(Parametri!$B$81+Parametri!$B$82, Parametri!$B$81+Parametri!$B$82*(B22+1)/Parametri!$B$83) -> 12.5 | Q22: =-IF(B22<10,Parametri!$B$51,IF(B22<20,Parametri!$B$54,Parametri!$B$57))*M22*G22/1000 -> -31.899774 | R22: =-Q22-Z22 -> 23.924831 | S22: =S21+R22 -> 277.12337 | T22: =-(Parametri!$B$86*(Parametri!$B$87*Parametri!$B$90+Parametri!$B$88*Parametri!$B$91+Parametri!$B$89*Parametri!$B$92)/1000000000)*MIN(B22+1,Parametri!$B$93) -> -2.85975 | U22: =IF(B22<Parametri!$B$125,Parametri!$B$46,IF(B22<Parametri!$B$126,Parametri!$B$47,Parametri!$B$48))*Parametri!$B$96*13/1000000000*((B22+1)*Parametri!$B$121+B22*(B22+1)/2*Parametri!$B$122) -> 38.255995 | V22: =IF(B22>=Parametri!$B$103-1,Parametri!$B$102*(1-Parametri!$B$127)^(B22-(Parametri!$B$103-1)),0) -> 4.6405256 | W22: =IF(B22>=Parametri!$B$105-1,Parametri!$B$104,0) -> 5 | X22: =IF(B22>=Parametri!$B$107-1,Parametri!$B$106+Parametri!$B$128*INT((B22-(Parametri!$B$107-1))/2),0) -> 3.87 | Y22: =IF(AND(B22>=Parametri!$B$109-1,B22<Parametri!$B$109-1+Parametri!$B$140),Parametri!$B$108,0) -> 0 | Z22: =IF(B22<10,Parametri!$B$52,IF(B22<20,Parametri!$B$55,0))*M22*G22/1000 -> 7.9749436 | AA22: =Parametri!$B$159*Parametri!$B$160 -> 0 | AB22: =(SUM(Z$5:Z22)+SUM(AA$5:AA22)-SUM(Z$5:Z7)-SUM(AA$5:AA7)) -> 98.568967 | AC22: =-(Parametri!$B$67*SUM(Z$5:Z22)+Parametri!$B$161*SUM(AA$5:AA22)) -> -1.6406597 | AD22: =-Z7-AA7 -> -4.1229868 | AE22: =Z22+AA22+N22+O22+P22+Q22+T22+U22+V22+W22+X22+Y22+AC22+AD22 -> 38.177998 | AF22: =AF21+AE22 -> 445.75059 | AG22: =-AF22/F22 -> -0.17401909 | AH22: =SUM(Z$5:Z22)-SUM(Z$5:Z7) -> 98.568967 | AI22: =-Z7 -> -4.1229868
A23: =Parametri!$B$6+B23 -> 2045 | B23: 18 | C23: =C22*(1+Parametri!$B$14) -> 24.835249 | D23: =D22*(1+Parametri!$B$15)+Parametri!$B$145*(1-Parametri!$B$15)^B22 -> 18.080553 | E23: =D23/C23 -> 0.72801978 | F23: =F22*(1+Parametri!$B$20) -> 2581.996 | G23: =G22*(1+Parametri!$B$22) -> 27677.716 | H23: =F23*I23 -> 422.15634 | I23: =IF(B23<=(Parametri!$B$35-Parametri!$B$6),Parametri!$B$32+(Parametri!$B$33-Parametri!$B$32)*B23/(Parametri!$B$35-Parametri!$B$6),Parametri!$B$33+(Parametri!$B$34-Parametri!$B$33)*(B23-(Parametri!$B$35-Parametri!$B$6))/(Parametri!$B$36-Parametri!$B$35)) -> 0.1635 | J23: =H23-AE23 -> 381.54685 | K23: =J23/F23 -> 0.14777205 | L23: =IF(B23<=5,Parametri!$B$58+(Parametri!$B$59-Parametri!$B$58)/5*B23,MIN(Parametri!$B$60,Parametri!$B$59+(Parametri!$B$60-Parametri!$B$59)/24*(B23-5))) -> 0.81666667 | M23: =L23*D23 -> 14.765785 | N23: =IF(B23<Parametri!$B$76,Parametri!$B$75*Parametri!$B$74*Parametri!$B$73/Parametri!$B$76,0) -> 0 | O23: =IF(B23<10,Parametri!$B$53,IF(B23<20,Parametri!$B$56,Parametri!$B$57))*M23*G23*Parametri!$B$72/1000 -> 6.6206677 | P23: =MIN(Parametri!$B$81+Parametri!$B$82, Parametri!$B$81+Parametri!$B$82*(B23+1)/Parametri!$B$83) -> 12.5 | Q23: =-IF(B23<10,Parametri!$B$51,IF(B23<20,Parametri!$B$54,Parametri!$B$57))*M23*G23/1000 -> -32.694655 | R23: =-Q23-Z23 -> 24.520992 | S23: =S22+R23 -> 301.64436 | T23: =-(Parametri!$B$86*(Parametri!$B$87*Parametri!$B$90+Parametri!$B$88*Parametri!$B$91+Parametri!$B$89*Parametri!$B$92)/1000000000)*MIN(B23+1,Parametri!$B$93) -> -2.85975 | U23: =IF(B23<Parametri!$B$125,Parametri!$B$46,IF(B23<Parametri!$B$126,Parametri!$B$47,Parametri!$B$48))*Parametri!$B$96*13/1000000000*((B23+1)*Parametri!$B$121+B23*(B23+1)/2*Parametri!$B$122) -> 41.840239 | V23: =IF(B23>=Parametri!$B$103-1,Parametri!$B$102*(1-Parametri!$B$127)^(B23-(Parametri!$B$103-1)),0) -> 4.5709177 | W23: =IF(B23>=Parametri!$B$105-1,Parametri!$B$104,0) -> 5 | X23: =IF(B23>=Parametri!$B$107-1,Parametri!$B$106+Parametri!$B$128*INT((B23-(Parametri!$B$107-1))/2),0) -> 3.87 | Y23: =IF(AND(B23>=Parametri!$B$109-1,B23<Parametri!$B$109-1+Parametri!$B$140),Parametri!$B$108,0) -> 0 | Z23: =IF(B23<10,Parametri!$B$52,IF(B23<20,Parametri!$B$55,0))*M23*G23/1000 -> 8.1736638 | AA23: =Parametri!$B$159*Parametri!$B$160 -> 0 | AB23: =(SUM(Z$5:Z23)+SUM(AA$5:AA23)-SUM(Z$5:Z8)-SUM(AA$5:AA8)) -> 102.0943 | AC23: =-(Parametri!$B$67*SUM(Z$5:Z23)+Parametri!$B$161*SUM(AA$5:AA23)) -> -1.7632647 | AD23: =-Z8-AA8 -> -4.648327 | AE23: =Z23+AA23+N23+O23+P23+Q23+T23+U23+V23+W23+X23+Y23+AC23+AD23 -> 40.609491 | AF23: =AF22+AE23 -> 486.36009 | AG23: =-AF23/F23 -> -0.18836593 | AH23: =SUM(Z$5:Z23)-SUM(Z$5:Z8) -> 102.0943 | AI23: =-Z8 -> -4.648327
A24: =Parametri!$B$6+B24 -> 2046 | B24: 19 | C24: =C23*(1+Parametri!$B$14) -> 24.98426 | D24: =D23*(1+Parametri!$B$15)+Parametri!$B$145*(1-Parametri!$B$15)^B23 -> 18.117046 | E24: =D24/C24 -> 0.72513836 | F24: =F23*(1+Parametri!$B$20) -> 2602.6519 | G24: =G23*(1+Parametri!$B$22) -> 27733.071 | H24: =F24*I24 -> 421.62962 | I24: =IF(B24<=(Parametri!$B$35-Parametri!$B$6),Parametri!$B$32+(Parametri!$B$33-Parametri!$B$32)*B24/(Parametri!$B$35-Parametri!$B$6),Parametri!$B$33+(Parametri!$B$34-Parametri!$B$33)*(B24-(Parametri!$B$35-Parametri!$B$6))/(Parametri!$B$36-Parametri!$B$35)) -> 0.162 | J24: =H24-AE24 -> 378.30453 | K24: =J24/F24 -> 0.14535349 | L24: =IF(B24<=5,Parametri!$B$58+(Parametri!$B$59-Parametri!$B$58)/5*B24,MIN(Parametri!$B$60,Parametri!$B$59+(Parametri!$B$60-Parametri!$B$59)/24*(B24-5))) -> 0.83333333 | M24: =L24*D24 -> 15.097538 | N24: =IF(B24<Parametri!$B$76,Parametri!$B$75*Parametri!$B$74*Parametri!$B$73/Parametri!$B$76,0) -> 0 | O24: =IF(B24<10,Parametri!$B$53,IF(B24<20,Parametri!$B$56,Parametri!$B$57))*M24*G24*Parametri!$B$72/1000 -> 6.7829578 | P24: =MIN(Parametri!$B$81+Parametri!$B$82, Parametri!$B$81+Parametri!$B$82*(B24+1)/Parametri!$B$83) -> 12.5 | Q24: =-IF(B24<10,Parametri!$B$51,IF(B24<20,Parametri!$B$54,Parametri!$B$57))*M24*G24/1000 -> -33.496088 | R24: =-Q24-Z24 -> 25.122066 | S24: =S23+R24 -> 326.76643 | T24: =-(Parametri!$B$86*(Parametri!$B$87*Parametri!$B$90+Parametri!$B$88*Parametri!$B$91+Parametri!$B$89*Parametri!$B$92)/1000000000)*MIN(B24+1,Parametri!$B$93) -> -2.85975 | U24: =IF(B24<Parametri!$B$125,Parametri!$B$46,IF(B24<Parametri!$B$126,Parametri!$B$47,Parametri!$B$48))*Parametri!$B$96*13/1000000000*((B24+1)*Parametri!$B$121+B24*(B24+1)/2*Parametri!$B$122) -> 45.578052 | V24: =IF(B24>=Parametri!$B$103-1,Parametri!$B$102*(1-Parametri!$B$127)^(B24-(Parametri!$B$103-1)),0) -> 4.5023539 | W24: =IF(B24>=Parametri!$B$105-1,Parametri!$B$104,0) -> 5 | X24: =IF(B24>=Parametri!$B$107-1,Parametri!$B$106+Parametri!$B$128*INT((B24-(Parametri!$B$107-1))/2),0) -> 4.01 | Y24: =IF(AND(B24>=Parametri!$B$109-1,B24<Parametri!$B$109-1+Parametri!$B$140),Parametri!$B$108,0) -> 0 | Z24: =IF(B24<10,Parametri!$B$52,IF(B24<20,Parametri!$B$55,0))*M24*G24/1000 -> 8.374022 | AA24: =Parametri!$B$159*Parametri!$B$160 -> 0 | AB24: =(SUM(Z$5:Z24)+SUM(AA$5:AA24)-SUM(Z$5:Z9)-SUM(AA$5:AA9)) -> 105.29074 | AC24: =-(Parametri!$B$67*SUM(Z$5:Z24)+Parametri!$B$161*SUM(AA$5:AA24)) -> -1.888875 | AD24: =-Z9-AA9 -> -5.1775889 | AE24: =Z24+AA24+N24+O24+P24+Q24+T24+U24+V24+W24+X24+Y24+AC24+AD24 -> 43.325084 | AF24: =AF23+AE24 -> 529.68517 | AG24: =-AF24/F24 -> -0.20351748 | AH24: =SUM(Z$5:Z24)-SUM(Z$5:Z9) -> 105.29074 | AI24: =-Z9 -> -5.1775889
A25: =Parametri!$B$6+B25 -> 2047 | B25: 20 | C25: =C24*(1+Parametri!$B$14) -> 25.134166 | D25: =D24*(1+Parametri!$B$15)+Parametri!$B$145*(1-Parametri!$B$15)^B24 -> 18.153991 | E25: =D25/C25 -> 0.72228339 | F25: =F24*(1+Parametri!$B$20) -> 2623.4732 | G25: =G24*(1+Parametri!$B$22) -> 27788.538 | H25: =F25*I25 -> 421.06744 | I25: =IF(B25<=(Parametri!$B$35-Parametri!$B$6),Parametri!$B$32+(Parametri!$B$33-Parametri!$B$32)*B25/(Parametri!$B$35-Parametri!$B$6),Parametri!$B$33+(Parametri!$B$34-Parametri!$B$33)*(B25-(Parametri!$B$35-Parametri!$B$6))/(Parametri!$B$36-Parametri!$B$35)) -> 0.1605 | J25: =H25-AE25 -> 384.28493 | K25: =J25/F25 -> 0.14647946 | L25: =IF(B25<=5,Parametri!$B$58+(Parametri!$B$59-Parametri!$B$58)/5*B25,MIN(Parametri!$B$60,Parametri!$B$59+(Parametri!$B$60-Parametri!$B$59)/24*(B25-5))) -> 0.85 | M25: =L25*D25 -> 15.430892 | N25: =IF(B25<Parametri!$B$76,Parametri!$B$75*Parametri!$B$74*Parametri!$B$73/Parametri!$B$76,0) -> 0 | O25: =IF(B25<10,Parametri!$B$53,IF(B25<20,Parametri!$B$56,Parametri!$B$57))*M25*G25*Parametri!$B$72/1000 -> 10.419887 | P25: =MIN(Parametri!$B$81+Parametri!$B$82, Parametri!$B$81+Parametri!$B$82*(B25+1)/Parametri!$B$83) -> 12.5 | Q25: =-IF(B25<10,Parametri!$B$51,IF(B25<20,Parametri!$B$54,Parametri!$B$57))*M25*G25/1000 -> -38.592173 | R25: =-Q25-Z25 -> 38.592173 | S25: =S24+R25 -> 365.3586 | T25: =-(Parametri!$B$86*(Parametri!$B$87*Parametri!$B$90+Parametri!$B$88*Parametri!$B$91+Parametri!$B$89*Parametri!$B$92)/1000000000)*MIN(B25+1,Parametri!$B$93) -> -2.85975 | U25: =IF(B25<Parametri!$B$125,Parametri!$B$46,IF(B25<Parametri!$B$126,Parametri!$B$47,Parametri!$B$48))*Parametri!$B$96*13/1000000000*((B25+1)*Parametri!$B$121+B25*(B25+1)/2*Parametri!$B$122) -> 49.469435 | V25: =IF(B25>=Parametri!$B$103-1,Parametri!$B$102*(1-Parametri!$B$127)^(B25-(Parametri!$B$103-1)),0) -> 4.4348186 | W25: =IF(B25>=Parametri!$B$105-1,Parametri!$B$104,0) -> 5 | X25: =IF(B25>=Parametri!$B$107-1,Parametri!$B$106+Parametri!$B$128*INT((B25-(Parametri!$B$107-1))/2),0) -> 4.01 | Y25: =IF(AND(B25>=Parametri!$B$109-1,B25<Parametri!$B$109-1+Parametri!$B$140),Parametri!$B$108,0) -> 0 | Z25: =IF(B25<10,Parametri!$B$52,IF(B25<20,Parametri!$B$55,0))*M25*G25/1000 -> 0 | AA25: =Parametri!$B$159*Parametri!$B$160 -> 0 | AB25: =(SUM(Z$5:Z25)+SUM(AA$5:AA25)-SUM(Z$5:Z10)-SUM(AA$5:AA10)) -> 99.579909 | AC25: =-(Parametri!$B$67*SUM(Z$5:Z25)+Parametri!$B$161*SUM(AA$5:AA25)) -> -1.888875 | AD25: =-Z10-AA10 -> -5.7108283 | AE25: =Z25+AA25+N25+O25+P25+Q25+T25+U25+V25+W25+X25+Y25+AC25+AD25 -> 36.782514 | AF25: =AF24+AE25 -> 566.46768 | AG25: =-AF25/F25 -> -0.2159228 | AH25: =SUM(Z$5:Z25)-SUM(Z$5:Z10) -> 99.579909 | AI25: =-Z10 -> -5.7108283
